2025-09-28 13:21:07.531 | ERROR    | - | Traceback (most recent call last):
  File "D:\Program Files\Python312\Lib\asyncio\selector_events.py", line 1013, in _read_ready__data_received
    data = self._sock.recv(self.max_size)
           ^^^^^^^^^^^^^^^^^^^^^^^^^^^^^^
ConnectionResetError: [WinError 10054] 远程主机强迫关闭了一个现有的连接。

The above exception was the direct cause of the following exception:

Traceback (most recent call last):
  File "D:\Projects\fastapi-samples\backend\.venv\Lib\site-packages\starlette\routing.py", line 693, in lifespan
    async with self.lifespan_context(app) as maybe_state:
               ^^^^^^^^^^^^^^^^^^^^^^^^^^
  File "D:\Program Files\Python312\Lib\contextlib.py", line 210, in __aenter__
    return await anext(self.gen)
           ^^^^^^^^^^^^^^^^^^^^^
  File "D:\Projects\fastapi-samples\backend\.venv\Lib\site-packages\fastapi_pagination\api.py", line 347, in lifespan
    async with _original_lifespan_context(app) as maybe_state:
               ^^^^^^^^^^^^^^^^^^^^^^^^^^^^^^^
  File "D:\Program Files\Python312\Lib\contextlib.py", line 210, in __aenter__
    return await anext(self.gen)
           ^^^^^^^^^^^^^^^^^^^^^
  File "D:\Projects\fastapi-samples\backend\.venv\Lib\site-packages\fastapi\routing.py", line 133, in merged_lifespan
    async with original_context(app) as maybe_original_state:
               ^^^^^^^^^^^^^^^^^^^^^
  File "D:\Program Files\Python312\Lib\contextlib.py", line 210, in __aenter__
    return await anext(self.gen)
           ^^^^^^^^^^^^^^^^^^^^^
  File "D:\Projects\fastapi-samples\backend\core\register.py", line 34, in register_init
    await create_tables()
  File "D:\Projects\fastapi-samples\backend\database\db.py", line 84, in create_tables
    async with async_engine.begin() as coon:
               ^^^^^^^^^^^^^^^^^^^^
  File "D:\Program Files\Python312\Lib\contextlib.py", line 210, in __aenter__
    return await anext(self.gen)
           ^^^^^^^^^^^^^^^^^^^^^
  File "D:\Projects\fastapi-samples\backend\.venv\Lib\site-packages\sqlalchemy\ext\asyncio\engine.py", line 1063, in begin
    async with conn:
               ^^^^
  File "D:\Projects\fastapi-samples\backend\.venv\Lib\site-packages\sqlalchemy\ext\asyncio\base.py", line 121, in __aenter__
    return await self.start(is_ctxmanager=True)
           ^^^^^^^^^^^^^^^^^^^^^^^^^^^^^^^^^^^^
  File "D:\Projects\fastapi-samples\backend\.venv\Lib\site-packages\sqlalchemy\ext\asyncio\engine.py", line 273, in start
    await greenlet_spawn(self.sync_engine.connect)
  File "D:\Projects\fastapi-samples\backend\.venv\Lib\site-packages\sqlalchemy\util\_concurrency_py3k.py", line 201, in greenlet_spawn
    result = context.throw(*sys.exc_info())
             ^^^^^^^^^^^^^^^^^^^^^^^^^^^^^^
  File "D:\Projects\fastapi-samples\backend\.venv\Lib\site-packages\sqlalchemy\engine\base.py", line 3278, in connect
    return self._connection_cls(self)
           ^^^^^^^^^^^^^^^^^^^^^^^^^^
  File "D:\Projects\fastapi-samples\backend\.venv\Lib\site-packages\sqlalchemy\engine\base.py", line 146, in __init__
    self._dbapi_connection = engine.raw_connection()
                             ^^^^^^^^^^^^^^^^^^^^^^^
  File "D:\Projects\fastapi-samples\backend\.venv\Lib\site-packages\sqlalchemy\engine\base.py", line 3302, in raw_connection
    return self.pool.connect()
           ^^^^^^^^^^^^^^^^^^^
  File "D:\Projects\fastapi-samples\backend\.venv\Lib\site-packages\sqlalchemy\pool\base.py", line 449, in connect
    return _ConnectionFairy._checkout(self)
           ^^^^^^^^^^^^^^^^^^^^^^^^^^^^^^^^
  File "D:\Projects\fastapi-samples\backend\.venv\Lib\site-packages\sqlalchemy\pool\base.py", line 1263, in _checkout
    fairy = _ConnectionRecord.checkout(pool)
            ^^^^^^^^^^^^^^^^^^^^^^^^^^^^^^^^
  File "D:\Projects\fastapi-samples\backend\.venv\Lib\site-packages\sqlalchemy\pool\base.py", line 712, in checkout
    rec = pool._do_get()
          ^^^^^^^^^^^^^^
  File "D:\Projects\fastapi-samples\backend\.venv\Lib\site-packages\sqlalchemy\pool\impl.py", line 179, in _do_get
    with util.safe_reraise():
         ^^^^^^^^^^^^^^^^^^^
  File "D:\Projects\fastapi-samples\backend\.venv\Lib\site-packages\sqlalchemy\util\langhelpers.py", line 146, in __exit__
    raise exc_value.with_traceback(exc_tb)
  File "D:\Projects\fastapi-samples\backend\.venv\Lib\site-packages\sqlalchemy\pool\impl.py", line 177, in _do_get
    return self._create_connection()
           ^^^^^^^^^^^^^^^^^^^^^^^^^
  File "D:\Projects\fastapi-samples\backend\.venv\Lib\site-packages\sqlalchemy\pool\base.py", line 390, in _create_connection
    return _ConnectionRecord(self)
           ^^^^^^^^^^^^^^^^^^^^^^^
  File "D:\Projects\fastapi-samples\backend\.venv\Lib\site-packages\sqlalchemy\pool\base.py", line 674, in __init__
    self.__connect()
  File "D:\Projects\fastapi-samples\backend\.venv\Lib\site-packages\sqlalchemy\pool\base.py", line 900, in __connect
    with util.safe_reraise():
         ^^^^^^^^^^^^^^^^^^^
  File "D:\Projects\fastapi-samples\backend\.venv\Lib\site-packages\sqlalchemy\util\langhelpers.py", line 146, in __exit__
    raise exc_value.with_traceback(exc_tb)
  File "D:\Projects\fastapi-samples\backend\.venv\Lib\site-packages\sqlalchemy\pool\base.py", line 896, in __connect
    self.dbapi_connection = connection = pool._invoke_creator(self)
                                         ^^^^^^^^^^^^^^^^^^^^^^^^^^
  File "D:\Projects\fastapi-samples\backend\.venv\Lib\site-packages\sqlalchemy\engine\create.py", line 643, in connect
    return dialect.connect(*cargs, **cparams)
           ^^^^^^^^^^^^^^^^^^^^^^^^^^^^^^^^^^
  File "D:\Projects\fastapi-samples\backend\.venv\Lib\site-packages\sqlalchemy\engine\default.py", line 621, in connect
    return self.loaded_dbapi.connect(*cargs, **cparams)
           ^^^^^^^^^^^^^^^^^^^^^^^^^^^^^^^^^^^^^^^^^^^^
  File "D:\Projects\fastapi-samples\backend\.venv\Lib\site-packages\sqlalchemy\dialects\postgresql\asyncpg.py", line 953, in connect
    await_only(creator_fn(*arg, **kw)),
    ^^^^^^^^^^^^^^^^^^^^^^^^^^^^^^^^^^
  File "D:\Projects\fastapi-samples\backend\.venv\Lib\site-packages\sqlalchemy\util\_concurrency_py3k.py", line 132, in await_only
    return current.parent.switch(awaitable)  # type: ignore[no-any-return,attr-defined] # noqa: E501
           ^^^^^^^^^^^^^^^^^^^^^^^^^^^^^^^^
  File "D:\Projects\fastapi-samples\backend\.venv\Lib\site-packages\sqlalchemy\util\_concurrency_py3k.py", line 196, in greenlet_spawn
    value = await result
            ^^^^^^^^^^^^
  File "D:\Projects\fastapi-samples\backend\.venv\Lib\site-packages\asyncpg\connection.py", line 2421, in connect
    return await connect_utils._connect(
           ^^^^^^^^^^^^^^^^^^^^^^^^^^^^^
  File "D:\Projects\fastapi-samples\backend\.venv\Lib\site-packages\asyncpg\connect_utils.py", line 1049, in _connect
    conn = await _connect_addr(
           ^^^^^^^^^^^^^^^^^^^^
  File "D:\Projects\fastapi-samples\backend\.venv\Lib\site-packages\asyncpg\connect_utils.py", line 886, in _connect_addr
    return await __connect_addr(params, True, *args)
           ^^^^^^^^^^^^^^^^^^^^^^^^^^^^^^^^^^^^^^^^^
  File "D:\Projects\fastapi-samples\backend\.venv\Lib\site-packages\asyncpg\connect_utils.py", line 934, in __connect_addr
    await connected
asyncpg.exceptions.ConnectionDoesNotExistError: connection was closed in the middle of operation

2025-09-28 13:21:07.535 | ERROR    | - | Application startup failed. Exiting.
2025-09-28 13:21:46.252 | ERROR    | - | Traceback (most recent call last):
  File "D:\Program Files\Python312\Lib\asyncio\selector_events.py", line 1013, in _read_ready__data_received
    data = self._sock.recv(self.max_size)
           ^^^^^^^^^^^^^^^^^^^^^^^^^^^^^^
ConnectionResetError: [WinError 10054] 远程主机强迫关闭了一个现有的连接。

The above exception was the direct cause of the following exception:

Traceback (most recent call last):
  File "D:\Projects\fastapi-samples\backend\.venv\Lib\site-packages\starlette\routing.py", line 693, in lifespan
    async with self.lifespan_context(app) as maybe_state:
               ^^^^^^^^^^^^^^^^^^^^^^^^^^
  File "D:\Program Files\Python312\Lib\contextlib.py", line 210, in __aenter__
    return await anext(self.gen)
           ^^^^^^^^^^^^^^^^^^^^^
  File "D:\Projects\fastapi-samples\backend\.venv\Lib\site-packages\fastapi_pagination\api.py", line 347, in lifespan
    async with _original_lifespan_context(app) as maybe_state:
               ^^^^^^^^^^^^^^^^^^^^^^^^^^^^^^^
  File "D:\Program Files\Python312\Lib\contextlib.py", line 210, in __aenter__
    return await anext(self.gen)
           ^^^^^^^^^^^^^^^^^^^^^
  File "D:\Projects\fastapi-samples\backend\.venv\Lib\site-packages\fastapi\routing.py", line 133, in merged_lifespan
    async with original_context(app) as maybe_original_state:
               ^^^^^^^^^^^^^^^^^^^^^
  File "D:\Program Files\Python312\Lib\contextlib.py", line 210, in __aenter__
    return await anext(self.gen)
           ^^^^^^^^^^^^^^^^^^^^^
  File "D:\Projects\fastapi-samples\backend\core\register.py", line 34, in register_init
    await create_tables()
  File "D:\Projects\fastapi-samples\backend\database\db.py", line 84, in create_tables
    async with async_engine.begin() as coon:
               ^^^^^^^^^^^^^^^^^^^^
  File "D:\Program Files\Python312\Lib\contextlib.py", line 210, in __aenter__
    return await anext(self.gen)
           ^^^^^^^^^^^^^^^^^^^^^
  File "D:\Projects\fastapi-samples\backend\.venv\Lib\site-packages\sqlalchemy\ext\asyncio\engine.py", line 1063, in begin
    async with conn:
               ^^^^
  File "D:\Projects\fastapi-samples\backend\.venv\Lib\site-packages\sqlalchemy\ext\asyncio\base.py", line 121, in __aenter__
    return await self.start(is_ctxmanager=True)
           ^^^^^^^^^^^^^^^^^^^^^^^^^^^^^^^^^^^^
  File "D:\Projects\fastapi-samples\backend\.venv\Lib\site-packages\sqlalchemy\ext\asyncio\engine.py", line 273, in start
    await greenlet_spawn(self.sync_engine.connect)
  File "D:\Projects\fastapi-samples\backend\.venv\Lib\site-packages\sqlalchemy\util\_concurrency_py3k.py", line 201, in greenlet_spawn
    result = context.throw(*sys.exc_info())
             ^^^^^^^^^^^^^^^^^^^^^^^^^^^^^^
  File "D:\Projects\fastapi-samples\backend\.venv\Lib\site-packages\sqlalchemy\engine\base.py", line 3278, in connect
    return self._connection_cls(self)
           ^^^^^^^^^^^^^^^^^^^^^^^^^^
  File "D:\Projects\fastapi-samples\backend\.venv\Lib\site-packages\sqlalchemy\engine\base.py", line 146, in __init__
    self._dbapi_connection = engine.raw_connection()
                             ^^^^^^^^^^^^^^^^^^^^^^^
  File "D:\Projects\fastapi-samples\backend\.venv\Lib\site-packages\sqlalchemy\engine\base.py", line 3302, in raw_connection
    return self.pool.connect()
           ^^^^^^^^^^^^^^^^^^^
  File "D:\Projects\fastapi-samples\backend\.venv\Lib\site-packages\sqlalchemy\pool\base.py", line 449, in connect
    return _ConnectionFairy._checkout(self)
           ^^^^^^^^^^^^^^^^^^^^^^^^^^^^^^^^
  File "D:\Projects\fastapi-samples\backend\.venv\Lib\site-packages\sqlalchemy\pool\base.py", line 1263, in _checkout
    fairy = _ConnectionRecord.checkout(pool)
            ^^^^^^^^^^^^^^^^^^^^^^^^^^^^^^^^
  File "D:\Projects\fastapi-samples\backend\.venv\Lib\site-packages\sqlalchemy\pool\base.py", line 712, in checkout
    rec = pool._do_get()
          ^^^^^^^^^^^^^^
  File "D:\Projects\fastapi-samples\backend\.venv\Lib\site-packages\sqlalchemy\pool\impl.py", line 179, in _do_get
    with util.safe_reraise():
         ^^^^^^^^^^^^^^^^^^^
  File "D:\Projects\fastapi-samples\backend\.venv\Lib\site-packages\sqlalchemy\util\langhelpers.py", line 146, in __exit__
    raise exc_value.with_traceback(exc_tb)
  File "D:\Projects\fastapi-samples\backend\.venv\Lib\site-packages\sqlalchemy\pool\impl.py", line 177, in _do_get
    return self._create_connection()
           ^^^^^^^^^^^^^^^^^^^^^^^^^
  File "D:\Projects\fastapi-samples\backend\.venv\Lib\site-packages\sqlalchemy\pool\base.py", line 390, in _create_connection
    return _ConnectionRecord(self)
           ^^^^^^^^^^^^^^^^^^^^^^^
  File "D:\Projects\fastapi-samples\backend\.venv\Lib\site-packages\sqlalchemy\pool\base.py", line 674, in __init__
    self.__connect()
  File "D:\Projects\fastapi-samples\backend\.venv\Lib\site-packages\sqlalchemy\pool\base.py", line 900, in __connect
    with util.safe_reraise():
         ^^^^^^^^^^^^^^^^^^^
  File "D:\Projects\fastapi-samples\backend\.venv\Lib\site-packages\sqlalchemy\util\langhelpers.py", line 146, in __exit__
    raise exc_value.with_traceback(exc_tb)
  File "D:\Projects\fastapi-samples\backend\.venv\Lib\site-packages\sqlalchemy\pool\base.py", line 896, in __connect
    self.dbapi_connection = connection = pool._invoke_creator(self)
                                         ^^^^^^^^^^^^^^^^^^^^^^^^^^
  File "D:\Projects\fastapi-samples\backend\.venv\Lib\site-packages\sqlalchemy\engine\create.py", line 643, in connect
    return dialect.connect(*cargs, **cparams)
           ^^^^^^^^^^^^^^^^^^^^^^^^^^^^^^^^^^
  File "D:\Projects\fastapi-samples\backend\.venv\Lib\site-packages\sqlalchemy\engine\default.py", line 621, in connect
    return self.loaded_dbapi.connect(*cargs, **cparams)
           ^^^^^^^^^^^^^^^^^^^^^^^^^^^^^^^^^^^^^^^^^^^^
  File "D:\Projects\fastapi-samples\backend\.venv\Lib\site-packages\sqlalchemy\dialects\postgresql\asyncpg.py", line 953, in connect
    await_only(creator_fn(*arg, **kw)),
    ^^^^^^^^^^^^^^^^^^^^^^^^^^^^^^^^^^
  File "D:\Projects\fastapi-samples\backend\.venv\Lib\site-packages\sqlalchemy\util\_concurrency_py3k.py", line 132, in await_only
    return current.parent.switch(awaitable)  # type: ignore[no-any-return,attr-defined] # noqa: E501
           ^^^^^^^^^^^^^^^^^^^^^^^^^^^^^^^^
  File "D:\Projects\fastapi-samples\backend\.venv\Lib\site-packages\sqlalchemy\util\_concurrency_py3k.py", line 196, in greenlet_spawn
    value = await result
            ^^^^^^^^^^^^
  File "D:\Projects\fastapi-samples\backend\.venv\Lib\site-packages\asyncpg\connection.py", line 2421, in connect
    return await connect_utils._connect(
           ^^^^^^^^^^^^^^^^^^^^^^^^^^^^^
  File "D:\Projects\fastapi-samples\backend\.venv\Lib\site-packages\asyncpg\connect_utils.py", line 1049, in _connect
    conn = await _connect_addr(
           ^^^^^^^^^^^^^^^^^^^^
  File "D:\Projects\fastapi-samples\backend\.venv\Lib\site-packages\asyncpg\connect_utils.py", line 886, in _connect_addr
    return await __connect_addr(params, True, *args)
           ^^^^^^^^^^^^^^^^^^^^^^^^^^^^^^^^^^^^^^^^^
  File "D:\Projects\fastapi-samples\backend\.venv\Lib\site-packages\asyncpg\connect_utils.py", line 934, in __connect_addr
    await connected
asyncpg.exceptions.ConnectionDoesNotExistError: connection was closed in the middle of operation

2025-09-28 13:21:46.258 | ERROR    | - | Application startup failed. Exiting.
2025-09-28 13:22:56.018 | ERROR    | - | Traceback (most recent call last):
  File "D:\Program Files\Python312\Lib\asyncio\selector_events.py", line 1013, in _read_ready__data_received
    data = self._sock.recv(self.max_size)
           ^^^^^^^^^^^^^^^^^^^^^^^^^^^^^^
ConnectionResetError: [WinError 10054] 远程主机强迫关闭了一个现有的连接。

The above exception was the direct cause of the following exception:

Traceback (most recent call last):
  File "D:\Projects\fastapi-samples\backend\.venv\Lib\site-packages\starlette\routing.py", line 693, in lifespan
    async with self.lifespan_context(app) as maybe_state:
               ^^^^^^^^^^^^^^^^^^^^^^^^^^
  File "D:\Program Files\Python312\Lib\contextlib.py", line 210, in __aenter__
    return await anext(self.gen)
           ^^^^^^^^^^^^^^^^^^^^^
  File "D:\Projects\fastapi-samples\backend\.venv\Lib\site-packages\fastapi_pagination\api.py", line 347, in lifespan
    async with _original_lifespan_context(app) as maybe_state:
               ^^^^^^^^^^^^^^^^^^^^^^^^^^^^^^^
  File "D:\Program Files\Python312\Lib\contextlib.py", line 210, in __aenter__
    return await anext(self.gen)
           ^^^^^^^^^^^^^^^^^^^^^
  File "D:\Projects\fastapi-samples\backend\.venv\Lib\site-packages\fastapi\routing.py", line 133, in merged_lifespan
    async with original_context(app) as maybe_original_state:
               ^^^^^^^^^^^^^^^^^^^^^
  File "D:\Program Files\Python312\Lib\contextlib.py", line 210, in __aenter__
    return await anext(self.gen)
           ^^^^^^^^^^^^^^^^^^^^^
  File "D:\Projects\fastapi-samples\backend\core\register.py", line 34, in register_init
    await create_tables()
  File "D:\Projects\fastapi-samples\backend\database\db.py", line 84, in create_tables
    async with async_engine.begin() as coon:
               ^^^^^^^^^^^^^^^^^^^^
  File "D:\Program Files\Python312\Lib\contextlib.py", line 210, in __aenter__
    return await anext(self.gen)
           ^^^^^^^^^^^^^^^^^^^^^
  File "D:\Projects\fastapi-samples\backend\.venv\Lib\site-packages\sqlalchemy\ext\asyncio\engine.py", line 1063, in begin
    async with conn:
               ^^^^
  File "D:\Projects\fastapi-samples\backend\.venv\Lib\site-packages\sqlalchemy\ext\asyncio\base.py", line 121, in __aenter__
    return await self.start(is_ctxmanager=True)
           ^^^^^^^^^^^^^^^^^^^^^^^^^^^^^^^^^^^^
  File "D:\Projects\fastapi-samples\backend\.venv\Lib\site-packages\sqlalchemy\ext\asyncio\engine.py", line 273, in start
    await greenlet_spawn(self.sync_engine.connect)
  File "D:\Projects\fastapi-samples\backend\.venv\Lib\site-packages\sqlalchemy\util\_concurrency_py3k.py", line 201, in greenlet_spawn
    result = context.throw(*sys.exc_info())
             ^^^^^^^^^^^^^^^^^^^^^^^^^^^^^^
  File "D:\Projects\fastapi-samples\backend\.venv\Lib\site-packages\sqlalchemy\engine\base.py", line 3278, in connect
    return self._connection_cls(self)
           ^^^^^^^^^^^^^^^^^^^^^^^^^^
  File "D:\Projects\fastapi-samples\backend\.venv\Lib\site-packages\sqlalchemy\engine\base.py", line 146, in __init__
    self._dbapi_connection = engine.raw_connection()
                             ^^^^^^^^^^^^^^^^^^^^^^^
  File "D:\Projects\fastapi-samples\backend\.venv\Lib\site-packages\sqlalchemy\engine\base.py", line 3302, in raw_connection
    return self.pool.connect()
           ^^^^^^^^^^^^^^^^^^^
  File "D:\Projects\fastapi-samples\backend\.venv\Lib\site-packages\sqlalchemy\pool\base.py", line 449, in connect
    return _ConnectionFairy._checkout(self)
           ^^^^^^^^^^^^^^^^^^^^^^^^^^^^^^^^
  File "D:\Projects\fastapi-samples\backend\.venv\Lib\site-packages\sqlalchemy\pool\base.py", line 1263, in _checkout
    fairy = _ConnectionRecord.checkout(pool)
            ^^^^^^^^^^^^^^^^^^^^^^^^^^^^^^^^
  File "D:\Projects\fastapi-samples\backend\.venv\Lib\site-packages\sqlalchemy\pool\base.py", line 712, in checkout
    rec = pool._do_get()
          ^^^^^^^^^^^^^^
  File "D:\Projects\fastapi-samples\backend\.venv\Lib\site-packages\sqlalchemy\pool\impl.py", line 179, in _do_get
    with util.safe_reraise():
         ^^^^^^^^^^^^^^^^^^^
  File "D:\Projects\fastapi-samples\backend\.venv\Lib\site-packages\sqlalchemy\util\langhelpers.py", line 146, in __exit__
    raise exc_value.with_traceback(exc_tb)
  File "D:\Projects\fastapi-samples\backend\.venv\Lib\site-packages\sqlalchemy\pool\impl.py", line 177, in _do_get
    return self._create_connection()
           ^^^^^^^^^^^^^^^^^^^^^^^^^
  File "D:\Projects\fastapi-samples\backend\.venv\Lib\site-packages\sqlalchemy\pool\base.py", line 390, in _create_connection
    return _ConnectionRecord(self)
           ^^^^^^^^^^^^^^^^^^^^^^^
  File "D:\Projects\fastapi-samples\backend\.venv\Lib\site-packages\sqlalchemy\pool\base.py", line 674, in __init__
    self.__connect()
  File "D:\Projects\fastapi-samples\backend\.venv\Lib\site-packages\sqlalchemy\pool\base.py", line 900, in __connect
    with util.safe_reraise():
         ^^^^^^^^^^^^^^^^^^^
  File "D:\Projects\fastapi-samples\backend\.venv\Lib\site-packages\sqlalchemy\util\langhelpers.py", line 146, in __exit__
    raise exc_value.with_traceback(exc_tb)
  File "D:\Projects\fastapi-samples\backend\.venv\Lib\site-packages\sqlalchemy\pool\base.py", line 896, in __connect
    self.dbapi_connection = connection = pool._invoke_creator(self)
                                         ^^^^^^^^^^^^^^^^^^^^^^^^^^
  File "D:\Projects\fastapi-samples\backend\.venv\Lib\site-packages\sqlalchemy\engine\create.py", line 643, in connect
    return dialect.connect(*cargs, **cparams)
           ^^^^^^^^^^^^^^^^^^^^^^^^^^^^^^^^^^
  File "D:\Projects\fastapi-samples\backend\.venv\Lib\site-packages\sqlalchemy\engine\default.py", line 621, in connect
    return self.loaded_dbapi.connect(*cargs, **cparams)
           ^^^^^^^^^^^^^^^^^^^^^^^^^^^^^^^^^^^^^^^^^^^^
  File "D:\Projects\fastapi-samples\backend\.venv\Lib\site-packages\sqlalchemy\dialects\postgresql\asyncpg.py", line 953, in connect
    await_only(creator_fn(*arg, **kw)),
    ^^^^^^^^^^^^^^^^^^^^^^^^^^^^^^^^^^
  File "D:\Projects\fastapi-samples\backend\.venv\Lib\site-packages\sqlalchemy\util\_concurrency_py3k.py", line 132, in await_only
    return current.parent.switch(awaitable)  # type: ignore[no-any-return,attr-defined] # noqa: E501
           ^^^^^^^^^^^^^^^^^^^^^^^^^^^^^^^^
  File "D:\Projects\fastapi-samples\backend\.venv\Lib\site-packages\sqlalchemy\util\_concurrency_py3k.py", line 196, in greenlet_spawn
    value = await result
            ^^^^^^^^^^^^
  File "D:\Projects\fastapi-samples\backend\.venv\Lib\site-packages\asyncpg\connection.py", line 2421, in connect
    return await connect_utils._connect(
           ^^^^^^^^^^^^^^^^^^^^^^^^^^^^^
  File "D:\Projects\fastapi-samples\backend\.venv\Lib\site-packages\asyncpg\connect_utils.py", line 1049, in _connect
    conn = await _connect_addr(
           ^^^^^^^^^^^^^^^^^^^^
  File "D:\Projects\fastapi-samples\backend\.venv\Lib\site-packages\asyncpg\connect_utils.py", line 886, in _connect_addr
    return await __connect_addr(params, True, *args)
           ^^^^^^^^^^^^^^^^^^^^^^^^^^^^^^^^^^^^^^^^^
  File "D:\Projects\fastapi-samples\backend\.venv\Lib\site-packages\asyncpg\connect_utils.py", line 934, in __connect_addr
    await connected
asyncpg.exceptions.ConnectionDoesNotExistError: connection was closed in the middle of operation

2025-09-28 13:22:56.024 | ERROR    | - | Application startup failed. Exiting.
2025-09-28 13:22:57.747 | ERROR    | - | Traceback (most recent call last):
  File "D:\Program Files\Python312\Lib\asyncio\selector_events.py", line 1013, in _read_ready__data_received
    data = self._sock.recv(self.max_size)
           ^^^^^^^^^^^^^^^^^^^^^^^^^^^^^^
ConnectionResetError: [WinError 10054] 远程主机强迫关闭了一个现有的连接。

The above exception was the direct cause of the following exception:

Traceback (most recent call last):
  File "D:\Projects\fastapi-samples\backend\.venv\Lib\site-packages\starlette\routing.py", line 693, in lifespan
    async with self.lifespan_context(app) as maybe_state:
               ^^^^^^^^^^^^^^^^^^^^^^^^^^
  File "D:\Program Files\Python312\Lib\contextlib.py", line 210, in __aenter__
    return await anext(self.gen)
           ^^^^^^^^^^^^^^^^^^^^^
  File "D:\Projects\fastapi-samples\backend\.venv\Lib\site-packages\fastapi_pagination\api.py", line 347, in lifespan
    async with _original_lifespan_context(app) as maybe_state:
               ^^^^^^^^^^^^^^^^^^^^^^^^^^^^^^^
  File "D:\Program Files\Python312\Lib\contextlib.py", line 210, in __aenter__
    return await anext(self.gen)
           ^^^^^^^^^^^^^^^^^^^^^
  File "D:\Projects\fastapi-samples\backend\.venv\Lib\site-packages\fastapi\routing.py", line 133, in merged_lifespan
    async with original_context(app) as maybe_original_state:
               ^^^^^^^^^^^^^^^^^^^^^
  File "D:\Program Files\Python312\Lib\contextlib.py", line 210, in __aenter__
    return await anext(self.gen)
           ^^^^^^^^^^^^^^^^^^^^^
  File "D:\Projects\fastapi-samples\backend\core\register.py", line 34, in register_init
    await create_tables()
  File "D:\Projects\fastapi-samples\backend\database\db.py", line 84, in create_tables
    async with async_engine.begin() as coon:
               ^^^^^^^^^^^^^^^^^^^^
  File "D:\Program Files\Python312\Lib\contextlib.py", line 210, in __aenter__
    return await anext(self.gen)
           ^^^^^^^^^^^^^^^^^^^^^
  File "D:\Projects\fastapi-samples\backend\.venv\Lib\site-packages\sqlalchemy\ext\asyncio\engine.py", line 1063, in begin
    async with conn:
               ^^^^
  File "D:\Projects\fastapi-samples\backend\.venv\Lib\site-packages\sqlalchemy\ext\asyncio\base.py", line 121, in __aenter__
    return await self.start(is_ctxmanager=True)
           ^^^^^^^^^^^^^^^^^^^^^^^^^^^^^^^^^^^^
  File "D:\Projects\fastapi-samples\backend\.venv\Lib\site-packages\sqlalchemy\ext\asyncio\engine.py", line 273, in start
    await greenlet_spawn(self.sync_engine.connect)
  File "D:\Projects\fastapi-samples\backend\.venv\Lib\site-packages\sqlalchemy\util\_concurrency_py3k.py", line 201, in greenlet_spawn
    result = context.throw(*sys.exc_info())
             ^^^^^^^^^^^^^^^^^^^^^^^^^^^^^^
  File "D:\Projects\fastapi-samples\backend\.venv\Lib\site-packages\sqlalchemy\engine\base.py", line 3278, in connect
    return self._connection_cls(self)
           ^^^^^^^^^^^^^^^^^^^^^^^^^^
  File "D:\Projects\fastapi-samples\backend\.venv\Lib\site-packages\sqlalchemy\engine\base.py", line 146, in __init__
    self._dbapi_connection = engine.raw_connection()
                             ^^^^^^^^^^^^^^^^^^^^^^^
  File "D:\Projects\fastapi-samples\backend\.venv\Lib\site-packages\sqlalchemy\engine\base.py", line 3302, in raw_connection
    return self.pool.connect()
           ^^^^^^^^^^^^^^^^^^^
  File "D:\Projects\fastapi-samples\backend\.venv\Lib\site-packages\sqlalchemy\pool\base.py", line 449, in connect
    return _ConnectionFairy._checkout(self)
           ^^^^^^^^^^^^^^^^^^^^^^^^^^^^^^^^
  File "D:\Projects\fastapi-samples\backend\.venv\Lib\site-packages\sqlalchemy\pool\base.py", line 1263, in _checkout
    fairy = _ConnectionRecord.checkout(pool)
            ^^^^^^^^^^^^^^^^^^^^^^^^^^^^^^^^
  File "D:\Projects\fastapi-samples\backend\.venv\Lib\site-packages\sqlalchemy\pool\base.py", line 712, in checkout
    rec = pool._do_get()
          ^^^^^^^^^^^^^^
  File "D:\Projects\fastapi-samples\backend\.venv\Lib\site-packages\sqlalchemy\pool\impl.py", line 179, in _do_get
    with util.safe_reraise():
         ^^^^^^^^^^^^^^^^^^^
  File "D:\Projects\fastapi-samples\backend\.venv\Lib\site-packages\sqlalchemy\util\langhelpers.py", line 146, in __exit__
    raise exc_value.with_traceback(exc_tb)
  File "D:\Projects\fastapi-samples\backend\.venv\Lib\site-packages\sqlalchemy\pool\impl.py", line 177, in _do_get
    return self._create_connection()
           ^^^^^^^^^^^^^^^^^^^^^^^^^
  File "D:\Projects\fastapi-samples\backend\.venv\Lib\site-packages\sqlalchemy\pool\base.py", line 390, in _create_connection
    return _ConnectionRecord(self)
           ^^^^^^^^^^^^^^^^^^^^^^^
  File "D:\Projects\fastapi-samples\backend\.venv\Lib\site-packages\sqlalchemy\pool\base.py", line 674, in __init__
    self.__connect()
  File "D:\Projects\fastapi-samples\backend\.venv\Lib\site-packages\sqlalchemy\pool\base.py", line 900, in __connect
    with util.safe_reraise():
         ^^^^^^^^^^^^^^^^^^^
  File "D:\Projects\fastapi-samples\backend\.venv\Lib\site-packages\sqlalchemy\util\langhelpers.py", line 146, in __exit__
    raise exc_value.with_traceback(exc_tb)
  File "D:\Projects\fastapi-samples\backend\.venv\Lib\site-packages\sqlalchemy\pool\base.py", line 896, in __connect
    self.dbapi_connection = connection = pool._invoke_creator(self)
                                         ^^^^^^^^^^^^^^^^^^^^^^^^^^
  File "D:\Projects\fastapi-samples\backend\.venv\Lib\site-packages\sqlalchemy\engine\create.py", line 643, in connect
    return dialect.connect(*cargs, **cparams)
           ^^^^^^^^^^^^^^^^^^^^^^^^^^^^^^^^^^
  File "D:\Projects\fastapi-samples\backend\.venv\Lib\site-packages\sqlalchemy\engine\default.py", line 621, in connect
    return self.loaded_dbapi.connect(*cargs, **cparams)
           ^^^^^^^^^^^^^^^^^^^^^^^^^^^^^^^^^^^^^^^^^^^^
  File "D:\Projects\fastapi-samples\backend\.venv\Lib\site-packages\sqlalchemy\dialects\postgresql\asyncpg.py", line 953, in connect
    await_only(creator_fn(*arg, **kw)),
    ^^^^^^^^^^^^^^^^^^^^^^^^^^^^^^^^^^
  File "D:\Projects\fastapi-samples\backend\.venv\Lib\site-packages\sqlalchemy\util\_concurrency_py3k.py", line 132, in await_only
    return current.parent.switch(awaitable)  # type: ignore[no-any-return,attr-defined] # noqa: E501
           ^^^^^^^^^^^^^^^^^^^^^^^^^^^^^^^^
  File "D:\Projects\fastapi-samples\backend\.venv\Lib\site-packages\sqlalchemy\util\_concurrency_py3k.py", line 196, in greenlet_spawn
    value = await result
            ^^^^^^^^^^^^
  File "D:\Projects\fastapi-samples\backend\.venv\Lib\site-packages\asyncpg\connection.py", line 2421, in connect
    return await connect_utils._connect(
           ^^^^^^^^^^^^^^^^^^^^^^^^^^^^^
  File "D:\Projects\fastapi-samples\backend\.venv\Lib\site-packages\asyncpg\connect_utils.py", line 1049, in _connect
    conn = await _connect_addr(
           ^^^^^^^^^^^^^^^^^^^^
  File "D:\Projects\fastapi-samples\backend\.venv\Lib\site-packages\asyncpg\connect_utils.py", line 886, in _connect_addr
    return await __connect_addr(params, True, *args)
           ^^^^^^^^^^^^^^^^^^^^^^^^^^^^^^^^^^^^^^^^^
  File "D:\Projects\fastapi-samples\backend\.venv\Lib\site-packages\asyncpg\connect_utils.py", line 934, in __connect_addr
    await connected
asyncpg.exceptions.ConnectionDoesNotExistError: connection was closed in the middle of operation

2025-09-28 13:22:57.753 | ERROR    | - | Application startup failed. Exiting.
2025-09-28 13:23:14.576 | ERROR    | - | Traceback (most recent call last):
  File "D:\Program Files\Python312\Lib\asyncio\selector_events.py", line 1013, in _read_ready__data_received
    data = self._sock.recv(self.max_size)
           ^^^^^^^^^^^^^^^^^^^^^^^^^^^^^^
ConnectionResetError: [WinError 10054] 远程主机强迫关闭了一个现有的连接。

The above exception was the direct cause of the following exception:

Traceback (most recent call last):
  File "D:\Projects\fastapi-samples\backend\.venv\Lib\site-packages\starlette\routing.py", line 693, in lifespan
    async with self.lifespan_context(app) as maybe_state:
               ^^^^^^^^^^^^^^^^^^^^^^^^^^
  File "D:\Program Files\Python312\Lib\contextlib.py", line 210, in __aenter__
    return await anext(self.gen)
           ^^^^^^^^^^^^^^^^^^^^^
  File "D:\Projects\fastapi-samples\backend\.venv\Lib\site-packages\fastapi_pagination\api.py", line 347, in lifespan
    async with _original_lifespan_context(app) as maybe_state:
               ^^^^^^^^^^^^^^^^^^^^^^^^^^^^^^^
  File "D:\Program Files\Python312\Lib\contextlib.py", line 210, in __aenter__
    return await anext(self.gen)
           ^^^^^^^^^^^^^^^^^^^^^
  File "D:\Projects\fastapi-samples\backend\.venv\Lib\site-packages\fastapi\routing.py", line 133, in merged_lifespan
    async with original_context(app) as maybe_original_state:
               ^^^^^^^^^^^^^^^^^^^^^
  File "D:\Program Files\Python312\Lib\contextlib.py", line 210, in __aenter__
    return await anext(self.gen)
           ^^^^^^^^^^^^^^^^^^^^^
  File "D:\Projects\fastapi-samples\backend\core\register.py", line 34, in register_init
    await create_tables()
  File "D:\Projects\fastapi-samples\backend\database\db.py", line 84, in create_tables
    async with async_engine.begin() as coon:
               ^^^^^^^^^^^^^^^^^^^^
  File "D:\Program Files\Python312\Lib\contextlib.py", line 210, in __aenter__
    return await anext(self.gen)
           ^^^^^^^^^^^^^^^^^^^^^
  File "D:\Projects\fastapi-samples\backend\.venv\Lib\site-packages\sqlalchemy\ext\asyncio\engine.py", line 1063, in begin
    async with conn:
               ^^^^
  File "D:\Projects\fastapi-samples\backend\.venv\Lib\site-packages\sqlalchemy\ext\asyncio\base.py", line 121, in __aenter__
    return await self.start(is_ctxmanager=True)
           ^^^^^^^^^^^^^^^^^^^^^^^^^^^^^^^^^^^^
  File "D:\Projects\fastapi-samples\backend\.venv\Lib\site-packages\sqlalchemy\ext\asyncio\engine.py", line 273, in start
    await greenlet_spawn(self.sync_engine.connect)
  File "D:\Projects\fastapi-samples\backend\.venv\Lib\site-packages\sqlalchemy\util\_concurrency_py3k.py", line 201, in greenlet_spawn
    result = context.throw(*sys.exc_info())
             ^^^^^^^^^^^^^^^^^^^^^^^^^^^^^^
  File "D:\Projects\fastapi-samples\backend\.venv\Lib\site-packages\sqlalchemy\engine\base.py", line 3278, in connect
    return self._connection_cls(self)
           ^^^^^^^^^^^^^^^^^^^^^^^^^^
  File "D:\Projects\fastapi-samples\backend\.venv\Lib\site-packages\sqlalchemy\engine\base.py", line 146, in __init__
    self._dbapi_connection = engine.raw_connection()
                             ^^^^^^^^^^^^^^^^^^^^^^^
  File "D:\Projects\fastapi-samples\backend\.venv\Lib\site-packages\sqlalchemy\engine\base.py", line 3302, in raw_connection
    return self.pool.connect()
           ^^^^^^^^^^^^^^^^^^^
  File "D:\Projects\fastapi-samples\backend\.venv\Lib\site-packages\sqlalchemy\pool\base.py", line 449, in connect
    return _ConnectionFairy._checkout(self)
           ^^^^^^^^^^^^^^^^^^^^^^^^^^^^^^^^
  File "D:\Projects\fastapi-samples\backend\.venv\Lib\site-packages\sqlalchemy\pool\base.py", line 1263, in _checkout
    fairy = _ConnectionRecord.checkout(pool)
            ^^^^^^^^^^^^^^^^^^^^^^^^^^^^^^^^
  File "D:\Projects\fastapi-samples\backend\.venv\Lib\site-packages\sqlalchemy\pool\base.py", line 712, in checkout
    rec = pool._do_get()
          ^^^^^^^^^^^^^^
  File "D:\Projects\fastapi-samples\backend\.venv\Lib\site-packages\sqlalchemy\pool\impl.py", line 179, in _do_get
    with util.safe_reraise():
         ^^^^^^^^^^^^^^^^^^^
  File "D:\Projects\fastapi-samples\backend\.venv\Lib\site-packages\sqlalchemy\util\langhelpers.py", line 146, in __exit__
    raise exc_value.with_traceback(exc_tb)
  File "D:\Projects\fastapi-samples\backend\.venv\Lib\site-packages\sqlalchemy\pool\impl.py", line 177, in _do_get
    return self._create_connection()
           ^^^^^^^^^^^^^^^^^^^^^^^^^
  File "D:\Projects\fastapi-samples\backend\.venv\Lib\site-packages\sqlalchemy\pool\base.py", line 390, in _create_connection
    return _ConnectionRecord(self)
           ^^^^^^^^^^^^^^^^^^^^^^^
  File "D:\Projects\fastapi-samples\backend\.venv\Lib\site-packages\sqlalchemy\pool\base.py", line 674, in __init__
    self.__connect()
  File "D:\Projects\fastapi-samples\backend\.venv\Lib\site-packages\sqlalchemy\pool\base.py", line 900, in __connect
    with util.safe_reraise():
         ^^^^^^^^^^^^^^^^^^^
  File "D:\Projects\fastapi-samples\backend\.venv\Lib\site-packages\sqlalchemy\util\langhelpers.py", line 146, in __exit__
    raise exc_value.with_traceback(exc_tb)
  File "D:\Projects\fastapi-samples\backend\.venv\Lib\site-packages\sqlalchemy\pool\base.py", line 896, in __connect
    self.dbapi_connection = connection = pool._invoke_creator(self)
                                         ^^^^^^^^^^^^^^^^^^^^^^^^^^
  File "D:\Projects\fastapi-samples\backend\.venv\Lib\site-packages\sqlalchemy\engine\create.py", line 643, in connect
    return dialect.connect(*cargs, **cparams)
           ^^^^^^^^^^^^^^^^^^^^^^^^^^^^^^^^^^
  File "D:\Projects\fastapi-samples\backend\.venv\Lib\site-packages\sqlalchemy\engine\default.py", line 621, in connect
    return self.loaded_dbapi.connect(*cargs, **cparams)
           ^^^^^^^^^^^^^^^^^^^^^^^^^^^^^^^^^^^^^^^^^^^^
  File "D:\Projects\fastapi-samples\backend\.venv\Lib\site-packages\sqlalchemy\dialects\postgresql\asyncpg.py", line 953, in connect
    await_only(creator_fn(*arg, **kw)),
    ^^^^^^^^^^^^^^^^^^^^^^^^^^^^^^^^^^
  File "D:\Projects\fastapi-samples\backend\.venv\Lib\site-packages\sqlalchemy\util\_concurrency_py3k.py", line 132, in await_only
    return current.parent.switch(awaitable)  # type: ignore[no-any-return,attr-defined] # noqa: E501
           ^^^^^^^^^^^^^^^^^^^^^^^^^^^^^^^^
  File "D:\Projects\fastapi-samples\backend\.venv\Lib\site-packages\sqlalchemy\util\_concurrency_py3k.py", line 196, in greenlet_spawn
    value = await result
            ^^^^^^^^^^^^
  File "D:\Projects\fastapi-samples\backend\.venv\Lib\site-packages\asyncpg\connection.py", line 2421, in connect
    return await connect_utils._connect(
           ^^^^^^^^^^^^^^^^^^^^^^^^^^^^^
  File "D:\Projects\fastapi-samples\backend\.venv\Lib\site-packages\asyncpg\connect_utils.py", line 1049, in _connect
    conn = await _connect_addr(
           ^^^^^^^^^^^^^^^^^^^^
  File "D:\Projects\fastapi-samples\backend\.venv\Lib\site-packages\asyncpg\connect_utils.py", line 886, in _connect_addr
    return await __connect_addr(params, True, *args)
           ^^^^^^^^^^^^^^^^^^^^^^^^^^^^^^^^^^^^^^^^^
  File "D:\Projects\fastapi-samples\backend\.venv\Lib\site-packages\asyncpg\connect_utils.py", line 934, in __connect_addr
    await connected
asyncpg.exceptions.ConnectionDoesNotExistError: connection was closed in the middle of operation

2025-09-28 13:23:14.582 | ERROR    | - | Application startup failed. Exiting.
2025-09-28 13:23:16.166 | ERROR    | - | Traceback (most recent call last):
  File "D:\Program Files\Python312\Lib\asyncio\selector_events.py", line 1013, in _read_ready__data_received
    data = self._sock.recv(self.max_size)
           ^^^^^^^^^^^^^^^^^^^^^^^^^^^^^^
ConnectionResetError: [WinError 10054] 远程主机强迫关闭了一个现有的连接。

The above exception was the direct cause of the following exception:

Traceback (most recent call last):
  File "D:\Projects\fastapi-samples\backend\.venv\Lib\site-packages\starlette\routing.py", line 693, in lifespan
    async with self.lifespan_context(app) as maybe_state:
               ^^^^^^^^^^^^^^^^^^^^^^^^^^
  File "D:\Program Files\Python312\Lib\contextlib.py", line 210, in __aenter__
    return await anext(self.gen)
           ^^^^^^^^^^^^^^^^^^^^^
  File "D:\Projects\fastapi-samples\backend\.venv\Lib\site-packages\fastapi_pagination\api.py", line 347, in lifespan
    async with _original_lifespan_context(app) as maybe_state:
               ^^^^^^^^^^^^^^^^^^^^^^^^^^^^^^^
  File "D:\Program Files\Python312\Lib\contextlib.py", line 210, in __aenter__
    return await anext(self.gen)
           ^^^^^^^^^^^^^^^^^^^^^
  File "D:\Projects\fastapi-samples\backend\.venv\Lib\site-packages\fastapi\routing.py", line 133, in merged_lifespan
    async with original_context(app) as maybe_original_state:
               ^^^^^^^^^^^^^^^^^^^^^
  File "D:\Program Files\Python312\Lib\contextlib.py", line 210, in __aenter__
    return await anext(self.gen)
           ^^^^^^^^^^^^^^^^^^^^^
  File "D:\Projects\fastapi-samples\backend\core\register.py", line 34, in register_init
    await create_tables()
  File "D:\Projects\fastapi-samples\backend\database\db.py", line 84, in create_tables
    async with async_engine.begin() as coon:
               ^^^^^^^^^^^^^^^^^^^^
  File "D:\Program Files\Python312\Lib\contextlib.py", line 210, in __aenter__
    return await anext(self.gen)
           ^^^^^^^^^^^^^^^^^^^^^
  File "D:\Projects\fastapi-samples\backend\.venv\Lib\site-packages\sqlalchemy\ext\asyncio\engine.py", line 1063, in begin
    async with conn:
               ^^^^
  File "D:\Projects\fastapi-samples\backend\.venv\Lib\site-packages\sqlalchemy\ext\asyncio\base.py", line 121, in __aenter__
    return await self.start(is_ctxmanager=True)
           ^^^^^^^^^^^^^^^^^^^^^^^^^^^^^^^^^^^^
  File "D:\Projects\fastapi-samples\backend\.venv\Lib\site-packages\sqlalchemy\ext\asyncio\engine.py", line 273, in start
    await greenlet_spawn(self.sync_engine.connect)
  File "D:\Projects\fastapi-samples\backend\.venv\Lib\site-packages\sqlalchemy\util\_concurrency_py3k.py", line 201, in greenlet_spawn
    result = context.throw(*sys.exc_info())
             ^^^^^^^^^^^^^^^^^^^^^^^^^^^^^^
  File "D:\Projects\fastapi-samples\backend\.venv\Lib\site-packages\sqlalchemy\engine\base.py", line 3278, in connect
    return self._connection_cls(self)
           ^^^^^^^^^^^^^^^^^^^^^^^^^^
  File "D:\Projects\fastapi-samples\backend\.venv\Lib\site-packages\sqlalchemy\engine\base.py", line 146, in __init__
    self._dbapi_connection = engine.raw_connection()
                             ^^^^^^^^^^^^^^^^^^^^^^^
  File "D:\Projects\fastapi-samples\backend\.venv\Lib\site-packages\sqlalchemy\engine\base.py", line 3302, in raw_connection
    return self.pool.connect()
           ^^^^^^^^^^^^^^^^^^^
  File "D:\Projects\fastapi-samples\backend\.venv\Lib\site-packages\sqlalchemy\pool\base.py", line 449, in connect
    return _ConnectionFairy._checkout(self)
           ^^^^^^^^^^^^^^^^^^^^^^^^^^^^^^^^
  File "D:\Projects\fastapi-samples\backend\.venv\Lib\site-packages\sqlalchemy\pool\base.py", line 1263, in _checkout
    fairy = _ConnectionRecord.checkout(pool)
            ^^^^^^^^^^^^^^^^^^^^^^^^^^^^^^^^
  File "D:\Projects\fastapi-samples\backend\.venv\Lib\site-packages\sqlalchemy\pool\base.py", line 712, in checkout
    rec = pool._do_get()
          ^^^^^^^^^^^^^^
  File "D:\Projects\fastapi-samples\backend\.venv\Lib\site-packages\sqlalchemy\pool\impl.py", line 179, in _do_get
    with util.safe_reraise():
         ^^^^^^^^^^^^^^^^^^^
  File "D:\Projects\fastapi-samples\backend\.venv\Lib\site-packages\sqlalchemy\util\langhelpers.py", line 146, in __exit__
    raise exc_value.with_traceback(exc_tb)
  File "D:\Projects\fastapi-samples\backend\.venv\Lib\site-packages\sqlalchemy\pool\impl.py", line 177, in _do_get
    return self._create_connection()
           ^^^^^^^^^^^^^^^^^^^^^^^^^
  File "D:\Projects\fastapi-samples\backend\.venv\Lib\site-packages\sqlalchemy\pool\base.py", line 390, in _create_connection
    return _ConnectionRecord(self)
           ^^^^^^^^^^^^^^^^^^^^^^^
  File "D:\Projects\fastapi-samples\backend\.venv\Lib\site-packages\sqlalchemy\pool\base.py", line 674, in __init__
    self.__connect()
  File "D:\Projects\fastapi-samples\backend\.venv\Lib\site-packages\sqlalchemy\pool\base.py", line 900, in __connect
    with util.safe_reraise():
         ^^^^^^^^^^^^^^^^^^^
  File "D:\Projects\fastapi-samples\backend\.venv\Lib\site-packages\sqlalchemy\util\langhelpers.py", line 146, in __exit__
    raise exc_value.with_traceback(exc_tb)
  File "D:\Projects\fastapi-samples\backend\.venv\Lib\site-packages\sqlalchemy\pool\base.py", line 896, in __connect
    self.dbapi_connection = connection = pool._invoke_creator(self)
                                         ^^^^^^^^^^^^^^^^^^^^^^^^^^
  File "D:\Projects\fastapi-samples\backend\.venv\Lib\site-packages\sqlalchemy\engine\create.py", line 643, in connect
    return dialect.connect(*cargs, **cparams)
           ^^^^^^^^^^^^^^^^^^^^^^^^^^^^^^^^^^
  File "D:\Projects\fastapi-samples\backend\.venv\Lib\site-packages\sqlalchemy\engine\default.py", line 621, in connect
    return self.loaded_dbapi.connect(*cargs, **cparams)
           ^^^^^^^^^^^^^^^^^^^^^^^^^^^^^^^^^^^^^^^^^^^^
  File "D:\Projects\fastapi-samples\backend\.venv\Lib\site-packages\sqlalchemy\dialects\postgresql\asyncpg.py", line 953, in connect
    await_only(creator_fn(*arg, **kw)),
    ^^^^^^^^^^^^^^^^^^^^^^^^^^^^^^^^^^
  File "D:\Projects\fastapi-samples\backend\.venv\Lib\site-packages\sqlalchemy\util\_concurrency_py3k.py", line 132, in await_only
    return current.parent.switch(awaitable)  # type: ignore[no-any-return,attr-defined] # noqa: E501
           ^^^^^^^^^^^^^^^^^^^^^^^^^^^^^^^^
  File "D:\Projects\fastapi-samples\backend\.venv\Lib\site-packages\sqlalchemy\util\_concurrency_py3k.py", line 196, in greenlet_spawn
    value = await result
            ^^^^^^^^^^^^
  File "D:\Projects\fastapi-samples\backend\.venv\Lib\site-packages\asyncpg\connection.py", line 2421, in connect
    return await connect_utils._connect(
           ^^^^^^^^^^^^^^^^^^^^^^^^^^^^^
  File "D:\Projects\fastapi-samples\backend\.venv\Lib\site-packages\asyncpg\connect_utils.py", line 1049, in _connect
    conn = await _connect_addr(
           ^^^^^^^^^^^^^^^^^^^^
  File "D:\Projects\fastapi-samples\backend\.venv\Lib\site-packages\asyncpg\connect_utils.py", line 886, in _connect_addr
    return await __connect_addr(params, True, *args)
           ^^^^^^^^^^^^^^^^^^^^^^^^^^^^^^^^^^^^^^^^^
  File "D:\Projects\fastapi-samples\backend\.venv\Lib\site-packages\asyncpg\connect_utils.py", line 934, in __connect_addr
    await connected
asyncpg.exceptions.ConnectionDoesNotExistError: connection was closed in the middle of operation

2025-09-28 13:23:16.172 | ERROR    | - | Application startup failed. Exiting.
2025-09-28 13:23:56.279 | ERROR    | - | Traceback (most recent call last):
  File "D:\Program Files\Python312\Lib\asyncio\selector_events.py", line 1013, in _read_ready__data_received
    data = self._sock.recv(self.max_size)
           ^^^^^^^^^^^^^^^^^^^^^^^^^^^^^^
ConnectionResetError: [WinError 10054] 远程主机强迫关闭了一个现有的连接。

The above exception was the direct cause of the following exception:

Traceback (most recent call last):
  File "D:\Projects\fastapi-samples\backend\.venv\Lib\site-packages\starlette\routing.py", line 693, in lifespan
    async with self.lifespan_context(app) as maybe_state:
               ^^^^^^^^^^^^^^^^^^^^^^^^^^
  File "D:\Program Files\Python312\Lib\contextlib.py", line 210, in __aenter__
    return await anext(self.gen)
           ^^^^^^^^^^^^^^^^^^^^^
  File "D:\Projects\fastapi-samples\backend\.venv\Lib\site-packages\fastapi_pagination\api.py", line 347, in lifespan
    async with _original_lifespan_context(app) as maybe_state:
               ^^^^^^^^^^^^^^^^^^^^^^^^^^^^^^^
  File "D:\Program Files\Python312\Lib\contextlib.py", line 210, in __aenter__
    return await anext(self.gen)
           ^^^^^^^^^^^^^^^^^^^^^
  File "D:\Projects\fastapi-samples\backend\.venv\Lib\site-packages\fastapi\routing.py", line 133, in merged_lifespan
    async with original_context(app) as maybe_original_state:
               ^^^^^^^^^^^^^^^^^^^^^
  File "D:\Program Files\Python312\Lib\contextlib.py", line 210, in __aenter__
    return await anext(self.gen)
           ^^^^^^^^^^^^^^^^^^^^^
  File "D:\Projects\fastapi-samples\backend\core\register.py", line 34, in register_init
    await create_tables()
  File "D:\Projects\fastapi-samples\backend\database\db.py", line 84, in create_tables
    async with async_engine.begin() as coon:
               ^^^^^^^^^^^^^^^^^^^^
  File "D:\Program Files\Python312\Lib\contextlib.py", line 210, in __aenter__
    return await anext(self.gen)
           ^^^^^^^^^^^^^^^^^^^^^
  File "D:\Projects\fastapi-samples\backend\.venv\Lib\site-packages\sqlalchemy\ext\asyncio\engine.py", line 1063, in begin
    async with conn:
               ^^^^
  File "D:\Projects\fastapi-samples\backend\.venv\Lib\site-packages\sqlalchemy\ext\asyncio\base.py", line 121, in __aenter__
    return await self.start(is_ctxmanager=True)
           ^^^^^^^^^^^^^^^^^^^^^^^^^^^^^^^^^^^^
  File "D:\Projects\fastapi-samples\backend\.venv\Lib\site-packages\sqlalchemy\ext\asyncio\engine.py", line 273, in start
    await greenlet_spawn(self.sync_engine.connect)
  File "D:\Projects\fastapi-samples\backend\.venv\Lib\site-packages\sqlalchemy\util\_concurrency_py3k.py", line 201, in greenlet_spawn
    result = context.throw(*sys.exc_info())
             ^^^^^^^^^^^^^^^^^^^^^^^^^^^^^^
  File "D:\Projects\fastapi-samples\backend\.venv\Lib\site-packages\sqlalchemy\engine\base.py", line 3278, in connect
    return self._connection_cls(self)
           ^^^^^^^^^^^^^^^^^^^^^^^^^^
  File "D:\Projects\fastapi-samples\backend\.venv\Lib\site-packages\sqlalchemy\engine\base.py", line 146, in __init__
    self._dbapi_connection = engine.raw_connection()
                             ^^^^^^^^^^^^^^^^^^^^^^^
  File "D:\Projects\fastapi-samples\backend\.venv\Lib\site-packages\sqlalchemy\engine\base.py", line 3302, in raw_connection
    return self.pool.connect()
           ^^^^^^^^^^^^^^^^^^^
  File "D:\Projects\fastapi-samples\backend\.venv\Lib\site-packages\sqlalchemy\pool\base.py", line 449, in connect
    return _ConnectionFairy._checkout(self)
           ^^^^^^^^^^^^^^^^^^^^^^^^^^^^^^^^
  File "D:\Projects\fastapi-samples\backend\.venv\Lib\site-packages\sqlalchemy\pool\base.py", line 1263, in _checkout
    fairy = _ConnectionRecord.checkout(pool)
            ^^^^^^^^^^^^^^^^^^^^^^^^^^^^^^^^
  File "D:\Projects\fastapi-samples\backend\.venv\Lib\site-packages\sqlalchemy\pool\base.py", line 712, in checkout
    rec = pool._do_get()
          ^^^^^^^^^^^^^^
  File "D:\Projects\fastapi-samples\backend\.venv\Lib\site-packages\sqlalchemy\pool\impl.py", line 179, in _do_get
    with util.safe_reraise():
         ^^^^^^^^^^^^^^^^^^^
  File "D:\Projects\fastapi-samples\backend\.venv\Lib\site-packages\sqlalchemy\util\langhelpers.py", line 146, in __exit__
    raise exc_value.with_traceback(exc_tb)
  File "D:\Projects\fastapi-samples\backend\.venv\Lib\site-packages\sqlalchemy\pool\impl.py", line 177, in _do_get
    return self._create_connection()
           ^^^^^^^^^^^^^^^^^^^^^^^^^
  File "D:\Projects\fastapi-samples\backend\.venv\Lib\site-packages\sqlalchemy\pool\base.py", line 390, in _create_connection
    return _ConnectionRecord(self)
           ^^^^^^^^^^^^^^^^^^^^^^^
  File "D:\Projects\fastapi-samples\backend\.venv\Lib\site-packages\sqlalchemy\pool\base.py", line 674, in __init__
    self.__connect()
  File "D:\Projects\fastapi-samples\backend\.venv\Lib\site-packages\sqlalchemy\pool\base.py", line 900, in __connect
    with util.safe_reraise():
         ^^^^^^^^^^^^^^^^^^^
  File "D:\Projects\fastapi-samples\backend\.venv\Lib\site-packages\sqlalchemy\util\langhelpers.py", line 146, in __exit__
    raise exc_value.with_traceback(exc_tb)
  File "D:\Projects\fastapi-samples\backend\.venv\Lib\site-packages\sqlalchemy\pool\base.py", line 896, in __connect
    self.dbapi_connection = connection = pool._invoke_creator(self)
                                         ^^^^^^^^^^^^^^^^^^^^^^^^^^
  File "D:\Projects\fastapi-samples\backend\.venv\Lib\site-packages\sqlalchemy\engine\create.py", line 643, in connect
    return dialect.connect(*cargs, **cparams)
           ^^^^^^^^^^^^^^^^^^^^^^^^^^^^^^^^^^
  File "D:\Projects\fastapi-samples\backend\.venv\Lib\site-packages\sqlalchemy\engine\default.py", line 621, in connect
    return self.loaded_dbapi.connect(*cargs, **cparams)
           ^^^^^^^^^^^^^^^^^^^^^^^^^^^^^^^^^^^^^^^^^^^^
  File "D:\Projects\fastapi-samples\backend\.venv\Lib\site-packages\sqlalchemy\dialects\postgresql\asyncpg.py", line 953, in connect
    await_only(creator_fn(*arg, **kw)),
    ^^^^^^^^^^^^^^^^^^^^^^^^^^^^^^^^^^
  File "D:\Projects\fastapi-samples\backend\.venv\Lib\site-packages\sqlalchemy\util\_concurrency_py3k.py", line 132, in await_only
    return current.parent.switch(awaitable)  # type: ignore[no-any-return,attr-defined] # noqa: E501
           ^^^^^^^^^^^^^^^^^^^^^^^^^^^^^^^^
  File "D:\Projects\fastapi-samples\backend\.venv\Lib\site-packages\sqlalchemy\util\_concurrency_py3k.py", line 196, in greenlet_spawn
    value = await result
            ^^^^^^^^^^^^
  File "D:\Projects\fastapi-samples\backend\.venv\Lib\site-packages\asyncpg\connection.py", line 2421, in connect
    return await connect_utils._connect(
           ^^^^^^^^^^^^^^^^^^^^^^^^^^^^^
  File "D:\Projects\fastapi-samples\backend\.venv\Lib\site-packages\asyncpg\connect_utils.py", line 1049, in _connect
    conn = await _connect_addr(
           ^^^^^^^^^^^^^^^^^^^^
  File "D:\Projects\fastapi-samples\backend\.venv\Lib\site-packages\asyncpg\connect_utils.py", line 886, in _connect_addr
    return await __connect_addr(params, True, *args)
           ^^^^^^^^^^^^^^^^^^^^^^^^^^^^^^^^^^^^^^^^^
  File "D:\Projects\fastapi-samples\backend\.venv\Lib\site-packages\asyncpg\connect_utils.py", line 934, in __connect_addr
    await connected
asyncpg.exceptions.ConnectionDoesNotExistError: connection was closed in the middle of operation

2025-09-28 13:23:56.284 | ERROR    | - | Application startup failed. Exiting.
2025-09-28 13:23:57.965 | ERROR    | - | Traceback (most recent call last):
  File "D:\Program Files\Python312\Lib\asyncio\selector_events.py", line 1013, in _read_ready__data_received
    data = self._sock.recv(self.max_size)
           ^^^^^^^^^^^^^^^^^^^^^^^^^^^^^^
ConnectionResetError: [WinError 10054] 远程主机强迫关闭了一个现有的连接。

The above exception was the direct cause of the following exception:

Traceback (most recent call last):
  File "D:\Projects\fastapi-samples\backend\.venv\Lib\site-packages\starlette\routing.py", line 693, in lifespan
    async with self.lifespan_context(app) as maybe_state:
               ^^^^^^^^^^^^^^^^^^^^^^^^^^
  File "D:\Program Files\Python312\Lib\contextlib.py", line 210, in __aenter__
    return await anext(self.gen)
           ^^^^^^^^^^^^^^^^^^^^^
  File "D:\Projects\fastapi-samples\backend\.venv\Lib\site-packages\fastapi_pagination\api.py", line 347, in lifespan
    async with _original_lifespan_context(app) as maybe_state:
               ^^^^^^^^^^^^^^^^^^^^^^^^^^^^^^^
  File "D:\Program Files\Python312\Lib\contextlib.py", line 210, in __aenter__
    return await anext(self.gen)
           ^^^^^^^^^^^^^^^^^^^^^
  File "D:\Projects\fastapi-samples\backend\.venv\Lib\site-packages\fastapi\routing.py", line 133, in merged_lifespan
    async with original_context(app) as maybe_original_state:
               ^^^^^^^^^^^^^^^^^^^^^
  File "D:\Program Files\Python312\Lib\contextlib.py", line 210, in __aenter__
    return await anext(self.gen)
           ^^^^^^^^^^^^^^^^^^^^^
  File "D:\Projects\fastapi-samples\backend\core\register.py", line 34, in register_init
    await create_tables()
  File "D:\Projects\fastapi-samples\backend\database\db.py", line 84, in create_tables
    async with async_engine.begin() as coon:
               ^^^^^^^^^^^^^^^^^^^^
  File "D:\Program Files\Python312\Lib\contextlib.py", line 210, in __aenter__
    return await anext(self.gen)
           ^^^^^^^^^^^^^^^^^^^^^
  File "D:\Projects\fastapi-samples\backend\.venv\Lib\site-packages\sqlalchemy\ext\asyncio\engine.py", line 1063, in begin
    async with conn:
               ^^^^
  File "D:\Projects\fastapi-samples\backend\.venv\Lib\site-packages\sqlalchemy\ext\asyncio\base.py", line 121, in __aenter__
    return await self.start(is_ctxmanager=True)
           ^^^^^^^^^^^^^^^^^^^^^^^^^^^^^^^^^^^^
  File "D:\Projects\fastapi-samples\backend\.venv\Lib\site-packages\sqlalchemy\ext\asyncio\engine.py", line 273, in start
    await greenlet_spawn(self.sync_engine.connect)
  File "D:\Projects\fastapi-samples\backend\.venv\Lib\site-packages\sqlalchemy\util\_concurrency_py3k.py", line 201, in greenlet_spawn
    result = context.throw(*sys.exc_info())
             ^^^^^^^^^^^^^^^^^^^^^^^^^^^^^^
  File "D:\Projects\fastapi-samples\backend\.venv\Lib\site-packages\sqlalchemy\engine\base.py", line 3278, in connect
    return self._connection_cls(self)
           ^^^^^^^^^^^^^^^^^^^^^^^^^^
  File "D:\Projects\fastapi-samples\backend\.venv\Lib\site-packages\sqlalchemy\engine\base.py", line 146, in __init__
    self._dbapi_connection = engine.raw_connection()
                             ^^^^^^^^^^^^^^^^^^^^^^^
  File "D:\Projects\fastapi-samples\backend\.venv\Lib\site-packages\sqlalchemy\engine\base.py", line 3302, in raw_connection
    return self.pool.connect()
           ^^^^^^^^^^^^^^^^^^^
  File "D:\Projects\fastapi-samples\backend\.venv\Lib\site-packages\sqlalchemy\pool\base.py", line 449, in connect
    return _ConnectionFairy._checkout(self)
           ^^^^^^^^^^^^^^^^^^^^^^^^^^^^^^^^
  File "D:\Projects\fastapi-samples\backend\.venv\Lib\site-packages\sqlalchemy\pool\base.py", line 1263, in _checkout
    fairy = _ConnectionRecord.checkout(pool)
            ^^^^^^^^^^^^^^^^^^^^^^^^^^^^^^^^
  File "D:\Projects\fastapi-samples\backend\.venv\Lib\site-packages\sqlalchemy\pool\base.py", line 712, in checkout
    rec = pool._do_get()
          ^^^^^^^^^^^^^^
  File "D:\Projects\fastapi-samples\backend\.venv\Lib\site-packages\sqlalchemy\pool\impl.py", line 179, in _do_get
    with util.safe_reraise():
         ^^^^^^^^^^^^^^^^^^^
  File "D:\Projects\fastapi-samples\backend\.venv\Lib\site-packages\sqlalchemy\util\langhelpers.py", line 146, in __exit__
    raise exc_value.with_traceback(exc_tb)
  File "D:\Projects\fastapi-samples\backend\.venv\Lib\site-packages\sqlalchemy\pool\impl.py", line 177, in _do_get
    return self._create_connection()
           ^^^^^^^^^^^^^^^^^^^^^^^^^
  File "D:\Projects\fastapi-samples\backend\.venv\Lib\site-packages\sqlalchemy\pool\base.py", line 390, in _create_connection
    return _ConnectionRecord(self)
           ^^^^^^^^^^^^^^^^^^^^^^^
  File "D:\Projects\fastapi-samples\backend\.venv\Lib\site-packages\sqlalchemy\pool\base.py", line 674, in __init__
    self.__connect()
  File "D:\Projects\fastapi-samples\backend\.venv\Lib\site-packages\sqlalchemy\pool\base.py", line 900, in __connect
    with util.safe_reraise():
         ^^^^^^^^^^^^^^^^^^^
  File "D:\Projects\fastapi-samples\backend\.venv\Lib\site-packages\sqlalchemy\util\langhelpers.py", line 146, in __exit__
    raise exc_value.with_traceback(exc_tb)
  File "D:\Projects\fastapi-samples\backend\.venv\Lib\site-packages\sqlalchemy\pool\base.py", line 896, in __connect
    self.dbapi_connection = connection = pool._invoke_creator(self)
                                         ^^^^^^^^^^^^^^^^^^^^^^^^^^
  File "D:\Projects\fastapi-samples\backend\.venv\Lib\site-packages\sqlalchemy\engine\create.py", line 643, in connect
    return dialect.connect(*cargs, **cparams)
           ^^^^^^^^^^^^^^^^^^^^^^^^^^^^^^^^^^
  File "D:\Projects\fastapi-samples\backend\.venv\Lib\site-packages\sqlalchemy\engine\default.py", line 621, in connect
    return self.loaded_dbapi.connect(*cargs, **cparams)
           ^^^^^^^^^^^^^^^^^^^^^^^^^^^^^^^^^^^^^^^^^^^^
  File "D:\Projects\fastapi-samples\backend\.venv\Lib\site-packages\sqlalchemy\dialects\postgresql\asyncpg.py", line 953, in connect
    await_only(creator_fn(*arg, **kw)),
    ^^^^^^^^^^^^^^^^^^^^^^^^^^^^^^^^^^
  File "D:\Projects\fastapi-samples\backend\.venv\Lib\site-packages\sqlalchemy\util\_concurrency_py3k.py", line 132, in await_only
    return current.parent.switch(awaitable)  # type: ignore[no-any-return,attr-defined] # noqa: E501
           ^^^^^^^^^^^^^^^^^^^^^^^^^^^^^^^^
  File "D:\Projects\fastapi-samples\backend\.venv\Lib\site-packages\sqlalchemy\util\_concurrency_py3k.py", line 196, in greenlet_spawn
    value = await result
            ^^^^^^^^^^^^
  File "D:\Projects\fastapi-samples\backend\.venv\Lib\site-packages\asyncpg\connection.py", line 2421, in connect
    return await connect_utils._connect(
           ^^^^^^^^^^^^^^^^^^^^^^^^^^^^^
  File "D:\Projects\fastapi-samples\backend\.venv\Lib\site-packages\asyncpg\connect_utils.py", line 1049, in _connect
    conn = await _connect_addr(
           ^^^^^^^^^^^^^^^^^^^^
  File "D:\Projects\fastapi-samples\backend\.venv\Lib\site-packages\asyncpg\connect_utils.py", line 886, in _connect_addr
    return await __connect_addr(params, True, *args)
           ^^^^^^^^^^^^^^^^^^^^^^^^^^^^^^^^^^^^^^^^^
  File "D:\Projects\fastapi-samples\backend\.venv\Lib\site-packages\asyncpg\connect_utils.py", line 934, in __connect_addr
    await connected
asyncpg.exceptions.ConnectionDoesNotExistError: connection was closed in the middle of operation

2025-09-28 13:23:57.973 | ERROR    | - | Application startup failed. Exiting.
2025-09-28 13:26:04.926 | ERROR    | - | Traceback (most recent call last):
  File "D:\Projects\fastapi-samples\backend\.venv\Lib\site-packages\sqlalchemy\engine\base.py", line 146, in __init__
    self._dbapi_connection = engine.raw_connection()
                             ^^^^^^^^^^^^^^^^^^^^^^^
  File "D:\Projects\fastapi-samples\backend\.venv\Lib\site-packages\sqlalchemy\engine\base.py", line 3302, in raw_connection
    return self.pool.connect()
           ^^^^^^^^^^^^^^^^^^^
  File "D:\Projects\fastapi-samples\backend\.venv\Lib\site-packages\sqlalchemy\pool\base.py", line 449, in connect
    return _ConnectionFairy._checkout(self)
           ^^^^^^^^^^^^^^^^^^^^^^^^^^^^^^^^
  File "D:\Projects\fastapi-samples\backend\.venv\Lib\site-packages\sqlalchemy\pool\base.py", line 1263, in _checkout
    fairy = _ConnectionRecord.checkout(pool)
            ^^^^^^^^^^^^^^^^^^^^^^^^^^^^^^^^
  File "D:\Projects\fastapi-samples\backend\.venv\Lib\site-packages\sqlalchemy\pool\base.py", line 712, in checkout
    rec = pool._do_get()
          ^^^^^^^^^^^^^^
  File "D:\Projects\fastapi-samples\backend\.venv\Lib\site-packages\sqlalchemy\pool\impl.py", line 308, in _do_get
    return self._create_connection()
           ^^^^^^^^^^^^^^^^^^^^^^^^^
  File "D:\Projects\fastapi-samples\backend\.venv\Lib\site-packages\sqlalchemy\pool\base.py", line 390, in _create_connection
    return _ConnectionRecord(self)
           ^^^^^^^^^^^^^^^^^^^^^^^
  File "D:\Projects\fastapi-samples\backend\.venv\Lib\site-packages\sqlalchemy\pool\base.py", line 674, in __init__
    self.__connect()
  File "D:\Projects\fastapi-samples\backend\.venv\Lib\site-packages\sqlalchemy\pool\base.py", line 900, in __connect
    with util.safe_reraise():
         ^^^^^^^^^^^^^^^^^^^
  File "D:\Projects\fastapi-samples\backend\.venv\Lib\site-packages\sqlalchemy\util\langhelpers.py", line 146, in __exit__
    raise exc_value.with_traceback(exc_tb)
  File "D:\Projects\fastapi-samples\backend\.venv\Lib\site-packages\sqlalchemy\pool\base.py", line 896, in __connect
    self.dbapi_connection = connection = pool._invoke_creator(self)
                                         ^^^^^^^^^^^^^^^^^^^^^^^^^^
  File "D:\Projects\fastapi-samples\backend\.venv\Lib\site-packages\sqlalchemy\engine\create.py", line 643, in connect
    return dialect.connect(*cargs, **cparams)
           ^^^^^^^^^^^^^^^^^^^^^^^^^^^^^^^^^^
  File "D:\Projects\fastapi-samples\backend\.venv\Lib\site-packages\sqlalchemy\engine\default.py", line 621, in connect
    return self.loaded_dbapi.connect(*cargs, **cparams)
           ^^^^^^^^^^^^^^^^^^^^^^^^^^^^^^^^^^^^^^^^^^^^
  File "D:\Projects\fastapi-samples\backend\.venv\Lib\site-packages\sqlalchemy\dialects\sqlite\aiosqlite.py", line 352, in connect
    await_only(connection),
    ^^^^^^^^^^^^^^^^^^^^^^
  File "D:\Projects\fastapi-samples\backend\.venv\Lib\site-packages\sqlalchemy\util\_concurrency_py3k.py", line 132, in await_only
    return current.parent.switch(awaitable)  # type: ignore[no-any-return,attr-defined] # noqa: E501
           ^^^^^^^^^^^^^^^^^^^^^^^^^^^^^^^^
  File "D:\Projects\fastapi-samples\backend\.venv\Lib\site-packages\sqlalchemy\util\_concurrency_py3k.py", line 196, in greenlet_spawn
    value = await result
            ^^^^^^^^^^^^
  File "D:\Projects\fastapi-samples\backend\.venv\Lib\site-packages\aiosqlite\core.py", line 130, in _connect
    self._connection = await future
                       ^^^^^^^^^^^^
  File "D:\Projects\fastapi-samples\backend\.venv\Lib\site-packages\aiosqlite\core.py", line 105, in run
    result = function()
             ^^^^^^^^^^
  File "D:\Projects\fastapi-samples\backend\.venv\Lib\site-packages\aiosqlite\core.py", line 382, in connector
    return sqlite3.connect(loc, **kwargs)
           ^^^^^^^^^^^^^^^^^^^^^^^^^^^^^^
sqlite3.OperationalError: unable to open database file

The above exception was the direct cause of the following exception:

Traceback (most recent call last):
  File "D:\Projects\fastapi-samples\backend\.venv\Lib\site-packages\starlette\routing.py", line 693, in lifespan
    async with self.lifespan_context(app) as maybe_state:
               ^^^^^^^^^^^^^^^^^^^^^^^^^^
  File "D:\Program Files\Python312\Lib\contextlib.py", line 210, in __aenter__
    return await anext(self.gen)
           ^^^^^^^^^^^^^^^^^^^^^
  File "D:\Projects\fastapi-samples\backend\.venv\Lib\site-packages\fastapi_pagination\api.py", line 347, in lifespan
    async with _original_lifespan_context(app) as maybe_state:
               ^^^^^^^^^^^^^^^^^^^^^^^^^^^^^^^
  File "D:\Program Files\Python312\Lib\contextlib.py", line 210, in __aenter__
    return await anext(self.gen)
           ^^^^^^^^^^^^^^^^^^^^^
  File "D:\Projects\fastapi-samples\backend\.venv\Lib\site-packages\fastapi\routing.py", line 133, in merged_lifespan
    async with original_context(app) as maybe_original_state:
               ^^^^^^^^^^^^^^^^^^^^^
  File "D:\Program Files\Python312\Lib\contextlib.py", line 210, in __aenter__
    return await anext(self.gen)
           ^^^^^^^^^^^^^^^^^^^^^
  File "D:\Projects\fastapi-samples\backend\core\register.py", line 34, in register_init
    await create_tables()
  File "D:\Projects\fastapi-samples\backend\database\db.py", line 106, in create_tables
    async with async_engine.begin() as coon:
               ^^^^^^^^^^^^^^^^^^^^
  File "D:\Program Files\Python312\Lib\contextlib.py", line 210, in __aenter__
    return await anext(self.gen)
           ^^^^^^^^^^^^^^^^^^^^^
  File "D:\Projects\fastapi-samples\backend\.venv\Lib\site-packages\sqlalchemy\ext\asyncio\engine.py", line 1063, in begin
    async with conn:
               ^^^^
  File "D:\Projects\fastapi-samples\backend\.venv\Lib\site-packages\sqlalchemy\ext\asyncio\base.py", line 121, in __aenter__
    return await self.start(is_ctxmanager=True)
           ^^^^^^^^^^^^^^^^^^^^^^^^^^^^^^^^^^^^
  File "D:\Projects\fastapi-samples\backend\.venv\Lib\site-packages\sqlalchemy\ext\asyncio\engine.py", line 273, in start
    await greenlet_spawn(self.sync_engine.connect)
  File "D:\Projects\fastapi-samples\backend\.venv\Lib\site-packages\sqlalchemy\util\_concurrency_py3k.py", line 201, in greenlet_spawn
    result = context.throw(*sys.exc_info())
             ^^^^^^^^^^^^^^^^^^^^^^^^^^^^^^
  File "D:\Projects\fastapi-samples\backend\.venv\Lib\site-packages\sqlalchemy\engine\base.py", line 3278, in connect
    return self._connection_cls(self)
           ^^^^^^^^^^^^^^^^^^^^^^^^^^
  File "D:\Projects\fastapi-samples\backend\.venv\Lib\site-packages\sqlalchemy\engine\base.py", line 148, in __init__
    Connection._handle_dbapi_exception_noconnection(
  File "D:\Projects\fastapi-samples\backend\.venv\Lib\site-packages\sqlalchemy\engine\base.py", line 2442, in _handle_dbapi_exception_noconnection
    raise sqlalchemy_exception.with_traceback(exc_info[2]) from e
  File "D:\Projects\fastapi-samples\backend\.venv\Lib\site-packages\sqlalchemy\engine\base.py", line 146, in __init__
    self._dbapi_connection = engine.raw_connection()
                             ^^^^^^^^^^^^^^^^^^^^^^^
  File "D:\Projects\fastapi-samples\backend\.venv\Lib\site-packages\sqlalchemy\engine\base.py", line 3302, in raw_connection
    return self.pool.connect()
           ^^^^^^^^^^^^^^^^^^^
  File "D:\Projects\fastapi-samples\backend\.venv\Lib\site-packages\sqlalchemy\pool\base.py", line 449, in connect
    return _ConnectionFairy._checkout(self)
           ^^^^^^^^^^^^^^^^^^^^^^^^^^^^^^^^
  File "D:\Projects\fastapi-samples\backend\.venv\Lib\site-packages\sqlalchemy\pool\base.py", line 1263, in _checkout
    fairy = _ConnectionRecord.checkout(pool)
            ^^^^^^^^^^^^^^^^^^^^^^^^^^^^^^^^
  File "D:\Projects\fastapi-samples\backend\.venv\Lib\site-packages\sqlalchemy\pool\base.py", line 712, in checkout
    rec = pool._do_get()
          ^^^^^^^^^^^^^^
  File "D:\Projects\fastapi-samples\backend\.venv\Lib\site-packages\sqlalchemy\pool\impl.py", line 308, in _do_get
    return self._create_connection()
           ^^^^^^^^^^^^^^^^^^^^^^^^^
  File "D:\Projects\fastapi-samples\backend\.venv\Lib\site-packages\sqlalchemy\pool\base.py", line 390, in _create_connection
    return _ConnectionRecord(self)
           ^^^^^^^^^^^^^^^^^^^^^^^
  File "D:\Projects\fastapi-samples\backend\.venv\Lib\site-packages\sqlalchemy\pool\base.py", line 674, in __init__
    self.__connect()
  File "D:\Projects\fastapi-samples\backend\.venv\Lib\site-packages\sqlalchemy\pool\base.py", line 900, in __connect
    with util.safe_reraise():
         ^^^^^^^^^^^^^^^^^^^
  File "D:\Projects\fastapi-samples\backend\.venv\Lib\site-packages\sqlalchemy\util\langhelpers.py", line 146, in __exit__
    raise exc_value.with_traceback(exc_tb)
  File "D:\Projects\fastapi-samples\backend\.venv\Lib\site-packages\sqlalchemy\pool\base.py", line 896, in __connect
    self.dbapi_connection = connection = pool._invoke_creator(self)
                                         ^^^^^^^^^^^^^^^^^^^^^^^^^^
  File "D:\Projects\fastapi-samples\backend\.venv\Lib\site-packages\sqlalchemy\engine\create.py", line 643, in connect
    return dialect.connect(*cargs, **cparams)
           ^^^^^^^^^^^^^^^^^^^^^^^^^^^^^^^^^^
  File "D:\Projects\fastapi-samples\backend\.venv\Lib\site-packages\sqlalchemy\engine\default.py", line 621, in connect
    return self.loaded_dbapi.connect(*cargs, **cparams)
           ^^^^^^^^^^^^^^^^^^^^^^^^^^^^^^^^^^^^^^^^^^^^
  File "D:\Projects\fastapi-samples\backend\.venv\Lib\site-packages\sqlalchemy\dialects\sqlite\aiosqlite.py", line 352, in connect
    await_only(connection),
    ^^^^^^^^^^^^^^^^^^^^^^
  File "D:\Projects\fastapi-samples\backend\.venv\Lib\site-packages\sqlalchemy\util\_concurrency_py3k.py", line 132, in await_only
    return current.parent.switch(awaitable)  # type: ignore[no-any-return,attr-defined] # noqa: E501
           ^^^^^^^^^^^^^^^^^^^^^^^^^^^^^^^^
  File "D:\Projects\fastapi-samples\backend\.venv\Lib\site-packages\sqlalchemy\util\_concurrency_py3k.py", line 196, in greenlet_spawn
    value = await result
            ^^^^^^^^^^^^
  File "D:\Projects\fastapi-samples\backend\.venv\Lib\site-packages\aiosqlite\core.py", line 130, in _connect
    self._connection = await future
                       ^^^^^^^^^^^^
  File "D:\Projects\fastapi-samples\backend\.venv\Lib\site-packages\aiosqlite\core.py", line 105, in run
    result = function()
             ^^^^^^^^^^
  File "D:\Projects\fastapi-samples\backend\.venv\Lib\site-packages\aiosqlite\core.py", line 382, in connector
    return sqlite3.connect(loc, **kwargs)
           ^^^^^^^^^^^^^^^^^^^^^^^^^^^^^^
sqlalchemy.exc.OperationalError: (sqlite3.OperationalError) unable to open database file
(Background on this error at: https://sqlalche.me/e/20/e3q8)

2025-09-28 13:26:04.933 | ERROR    | - | Application startup failed. Exiting.
2025-09-28 13:26:06.309 | ERROR    | - | Traceback (most recent call last):
  File "D:\Projects\fastapi-samples\backend\.venv\Lib\site-packages\sqlalchemy\engine\base.py", line 146, in __init__
    self._dbapi_connection = engine.raw_connection()
                             ^^^^^^^^^^^^^^^^^^^^^^^
  File "D:\Projects\fastapi-samples\backend\.venv\Lib\site-packages\sqlalchemy\engine\base.py", line 3302, in raw_connection
    return self.pool.connect()
           ^^^^^^^^^^^^^^^^^^^
  File "D:\Projects\fastapi-samples\backend\.venv\Lib\site-packages\sqlalchemy\pool\base.py", line 449, in connect
    return _ConnectionFairy._checkout(self)
           ^^^^^^^^^^^^^^^^^^^^^^^^^^^^^^^^
  File "D:\Projects\fastapi-samples\backend\.venv\Lib\site-packages\sqlalchemy\pool\base.py", line 1263, in _checkout
    fairy = _ConnectionRecord.checkout(pool)
            ^^^^^^^^^^^^^^^^^^^^^^^^^^^^^^^^
  File "D:\Projects\fastapi-samples\backend\.venv\Lib\site-packages\sqlalchemy\pool\base.py", line 712, in checkout
    rec = pool._do_get()
          ^^^^^^^^^^^^^^
  File "D:\Projects\fastapi-samples\backend\.venv\Lib\site-packages\sqlalchemy\pool\impl.py", line 308, in _do_get
    return self._create_connection()
           ^^^^^^^^^^^^^^^^^^^^^^^^^
  File "D:\Projects\fastapi-samples\backend\.venv\Lib\site-packages\sqlalchemy\pool\base.py", line 390, in _create_connection
    return _ConnectionRecord(self)
           ^^^^^^^^^^^^^^^^^^^^^^^
  File "D:\Projects\fastapi-samples\backend\.venv\Lib\site-packages\sqlalchemy\pool\base.py", line 674, in __init__
    self.__connect()
  File "D:\Projects\fastapi-samples\backend\.venv\Lib\site-packages\sqlalchemy\pool\base.py", line 900, in __connect
    with util.safe_reraise():
         ^^^^^^^^^^^^^^^^^^^
  File "D:\Projects\fastapi-samples\backend\.venv\Lib\site-packages\sqlalchemy\util\langhelpers.py", line 146, in __exit__
    raise exc_value.with_traceback(exc_tb)
  File "D:\Projects\fastapi-samples\backend\.venv\Lib\site-packages\sqlalchemy\pool\base.py", line 896, in __connect
    self.dbapi_connection = connection = pool._invoke_creator(self)
                                         ^^^^^^^^^^^^^^^^^^^^^^^^^^
  File "D:\Projects\fastapi-samples\backend\.venv\Lib\site-packages\sqlalchemy\engine\create.py", line 643, in connect
    return dialect.connect(*cargs, **cparams)
           ^^^^^^^^^^^^^^^^^^^^^^^^^^^^^^^^^^
  File "D:\Projects\fastapi-samples\backend\.venv\Lib\site-packages\sqlalchemy\engine\default.py", line 621, in connect
    return self.loaded_dbapi.connect(*cargs, **cparams)
           ^^^^^^^^^^^^^^^^^^^^^^^^^^^^^^^^^^^^^^^^^^^^
  File "D:\Projects\fastapi-samples\backend\.venv\Lib\site-packages\sqlalchemy\dialects\sqlite\aiosqlite.py", line 352, in connect
    await_only(connection),
    ^^^^^^^^^^^^^^^^^^^^^^
  File "D:\Projects\fastapi-samples\backend\.venv\Lib\site-packages\sqlalchemy\util\_concurrency_py3k.py", line 132, in await_only
    return current.parent.switch(awaitable)  # type: ignore[no-any-return,attr-defined] # noqa: E501
           ^^^^^^^^^^^^^^^^^^^^^^^^^^^^^^^^
  File "D:\Projects\fastapi-samples\backend\.venv\Lib\site-packages\sqlalchemy\util\_concurrency_py3k.py", line 196, in greenlet_spawn
    value = await result
            ^^^^^^^^^^^^
  File "D:\Projects\fastapi-samples\backend\.venv\Lib\site-packages\aiosqlite\core.py", line 130, in _connect
    self._connection = await future
                       ^^^^^^^^^^^^
  File "D:\Projects\fastapi-samples\backend\.venv\Lib\site-packages\aiosqlite\core.py", line 105, in run
    result = function()
             ^^^^^^^^^^
  File "D:\Projects\fastapi-samples\backend\.venv\Lib\site-packages\aiosqlite\core.py", line 382, in connector
    return sqlite3.connect(loc, **kwargs)
           ^^^^^^^^^^^^^^^^^^^^^^^^^^^^^^
sqlite3.OperationalError: unable to open database file

The above exception was the direct cause of the following exception:

Traceback (most recent call last):
  File "D:\Projects\fastapi-samples\backend\.venv\Lib\site-packages\starlette\routing.py", line 693, in lifespan
    async with self.lifespan_context(app) as maybe_state:
               ^^^^^^^^^^^^^^^^^^^^^^^^^^
  File "D:\Program Files\Python312\Lib\contextlib.py", line 210, in __aenter__
    return await anext(self.gen)
           ^^^^^^^^^^^^^^^^^^^^^
  File "D:\Projects\fastapi-samples\backend\.venv\Lib\site-packages\fastapi_pagination\api.py", line 347, in lifespan
    async with _original_lifespan_context(app) as maybe_state:
               ^^^^^^^^^^^^^^^^^^^^^^^^^^^^^^^
  File "D:\Program Files\Python312\Lib\contextlib.py", line 210, in __aenter__
    return await anext(self.gen)
           ^^^^^^^^^^^^^^^^^^^^^
  File "D:\Projects\fastapi-samples\backend\.venv\Lib\site-packages\fastapi\routing.py", line 133, in merged_lifespan
    async with original_context(app) as maybe_original_state:
               ^^^^^^^^^^^^^^^^^^^^^
  File "D:\Program Files\Python312\Lib\contextlib.py", line 210, in __aenter__
    return await anext(self.gen)
           ^^^^^^^^^^^^^^^^^^^^^
  File "D:\Projects\fastapi-samples\backend\core\register.py", line 34, in register_init
    await create_tables()
  File "D:\Projects\fastapi-samples\backend\database\db.py", line 106, in create_tables
    async with async_engine.begin() as coon:
               ^^^^^^^^^^^^^^^^^^^^
  File "D:\Program Files\Python312\Lib\contextlib.py", line 210, in __aenter__
    return await anext(self.gen)
           ^^^^^^^^^^^^^^^^^^^^^
  File "D:\Projects\fastapi-samples\backend\.venv\Lib\site-packages\sqlalchemy\ext\asyncio\engine.py", line 1063, in begin
    async with conn:
               ^^^^
  File "D:\Projects\fastapi-samples\backend\.venv\Lib\site-packages\sqlalchemy\ext\asyncio\base.py", line 121, in __aenter__
    return await self.start(is_ctxmanager=True)
           ^^^^^^^^^^^^^^^^^^^^^^^^^^^^^^^^^^^^
  File "D:\Projects\fastapi-samples\backend\.venv\Lib\site-packages\sqlalchemy\ext\asyncio\engine.py", line 273, in start
    await greenlet_spawn(self.sync_engine.connect)
  File "D:\Projects\fastapi-samples\backend\.venv\Lib\site-packages\sqlalchemy\util\_concurrency_py3k.py", line 201, in greenlet_spawn
    result = context.throw(*sys.exc_info())
             ^^^^^^^^^^^^^^^^^^^^^^^^^^^^^^
  File "D:\Projects\fastapi-samples\backend\.venv\Lib\site-packages\sqlalchemy\engine\base.py", line 3278, in connect
    return self._connection_cls(self)
           ^^^^^^^^^^^^^^^^^^^^^^^^^^
  File "D:\Projects\fastapi-samples\backend\.venv\Lib\site-packages\sqlalchemy\engine\base.py", line 148, in __init__
    Connection._handle_dbapi_exception_noconnection(
  File "D:\Projects\fastapi-samples\backend\.venv\Lib\site-packages\sqlalchemy\engine\base.py", line 2442, in _handle_dbapi_exception_noconnection
    raise sqlalchemy_exception.with_traceback(exc_info[2]) from e
  File "D:\Projects\fastapi-samples\backend\.venv\Lib\site-packages\sqlalchemy\engine\base.py", line 146, in __init__
    self._dbapi_connection = engine.raw_connection()
                             ^^^^^^^^^^^^^^^^^^^^^^^
  File "D:\Projects\fastapi-samples\backend\.venv\Lib\site-packages\sqlalchemy\engine\base.py", line 3302, in raw_connection
    return self.pool.connect()
           ^^^^^^^^^^^^^^^^^^^
  File "D:\Projects\fastapi-samples\backend\.venv\Lib\site-packages\sqlalchemy\pool\base.py", line 449, in connect
    return _ConnectionFairy._checkout(self)
           ^^^^^^^^^^^^^^^^^^^^^^^^^^^^^^^^
  File "D:\Projects\fastapi-samples\backend\.venv\Lib\site-packages\sqlalchemy\pool\base.py", line 1263, in _checkout
    fairy = _ConnectionRecord.checkout(pool)
            ^^^^^^^^^^^^^^^^^^^^^^^^^^^^^^^^
  File "D:\Projects\fastapi-samples\backend\.venv\Lib\site-packages\sqlalchemy\pool\base.py", line 712, in checkout
    rec = pool._do_get()
          ^^^^^^^^^^^^^^
  File "D:\Projects\fastapi-samples\backend\.venv\Lib\site-packages\sqlalchemy\pool\impl.py", line 308, in _do_get
    return self._create_connection()
           ^^^^^^^^^^^^^^^^^^^^^^^^^
  File "D:\Projects\fastapi-samples\backend\.venv\Lib\site-packages\sqlalchemy\pool\base.py", line 390, in _create_connection
    return _ConnectionRecord(self)
           ^^^^^^^^^^^^^^^^^^^^^^^
  File "D:\Projects\fastapi-samples\backend\.venv\Lib\site-packages\sqlalchemy\pool\base.py", line 674, in __init__
    self.__connect()
  File "D:\Projects\fastapi-samples\backend\.venv\Lib\site-packages\sqlalchemy\pool\base.py", line 900, in __connect
    with util.safe_reraise():
         ^^^^^^^^^^^^^^^^^^^
  File "D:\Projects\fastapi-samples\backend\.venv\Lib\site-packages\sqlalchemy\util\langhelpers.py", line 146, in __exit__
    raise exc_value.with_traceback(exc_tb)
  File "D:\Projects\fastapi-samples\backend\.venv\Lib\site-packages\sqlalchemy\pool\base.py", line 896, in __connect
    self.dbapi_connection = connection = pool._invoke_creator(self)
                                         ^^^^^^^^^^^^^^^^^^^^^^^^^^
  File "D:\Projects\fastapi-samples\backend\.venv\Lib\site-packages\sqlalchemy\engine\create.py", line 643, in connect
    return dialect.connect(*cargs, **cparams)
           ^^^^^^^^^^^^^^^^^^^^^^^^^^^^^^^^^^
  File "D:\Projects\fastapi-samples\backend\.venv\Lib\site-packages\sqlalchemy\engine\default.py", line 621, in connect
    return self.loaded_dbapi.connect(*cargs, **cparams)
           ^^^^^^^^^^^^^^^^^^^^^^^^^^^^^^^^^^^^^^^^^^^^
  File "D:\Projects\fastapi-samples\backend\.venv\Lib\site-packages\sqlalchemy\dialects\sqlite\aiosqlite.py", line 352, in connect
    await_only(connection),
    ^^^^^^^^^^^^^^^^^^^^^^
  File "D:\Projects\fastapi-samples\backend\.venv\Lib\site-packages\sqlalchemy\util\_concurrency_py3k.py", line 132, in await_only
    return current.parent.switch(awaitable)  # type: ignore[no-any-return,attr-defined] # noqa: E501
           ^^^^^^^^^^^^^^^^^^^^^^^^^^^^^^^^
  File "D:\Projects\fastapi-samples\backend\.venv\Lib\site-packages\sqlalchemy\util\_concurrency_py3k.py", line 196, in greenlet_spawn
    value = await result
            ^^^^^^^^^^^^
  File "D:\Projects\fastapi-samples\backend\.venv\Lib\site-packages\aiosqlite\core.py", line 130, in _connect
    self._connection = await future
                       ^^^^^^^^^^^^
  File "D:\Projects\fastapi-samples\backend\.venv\Lib\site-packages\aiosqlite\core.py", line 105, in run
    result = function()
             ^^^^^^^^^^
  File "D:\Projects\fastapi-samples\backend\.venv\Lib\site-packages\aiosqlite\core.py", line 382, in connector
    return sqlite3.connect(loc, **kwargs)
           ^^^^^^^^^^^^^^^^^^^^^^^^^^^^^^
sqlalchemy.exc.OperationalError: (sqlite3.OperationalError) unable to open database file
(Background on this error at: https://sqlalche.me/e/20/e3q8)

2025-09-28 13:26:06.316 | ERROR    | - | Application startup failed. Exiting.
2025-09-28 13:39:47.571 | ERROR    | - | ❌ 数据库 redis 连接认证失败
2025-09-28 13:39:47.584 | ERROR    | - | Traceback (most recent call last):
  File "D:\Projects\fastapi-samples\backend\database\redis.py", line 31, in open
    await self.ping()
  File "D:\Projects\fastapi-samples\backend\.venv\Lib\site-packages\redis\asyncio\client.py", line 672, in execute_command
    conn = self.connection or await pool.get_connection()
                              ^^^^^^^^^^^^^^^^^^^^^^^^^^^
  File "D:\Projects\fastapi-samples\backend\.venv\Lib\site-packages\redis\asyncio\connection.py", line 1149, in get_connection
    await self.ensure_connection(connection)
  File "D:\Projects\fastapi-samples\backend\.venv\Lib\site-packages\redis\asyncio\connection.py", line 1182, in ensure_connection
    await connection.connect()
  File "D:\Projects\fastapi-samples\backend\.venv\Lib\site-packages\redis\asyncio\connection.py", line 296, in connect
    await self.connect_check_health(check_health=True)
  File "D:\Projects\fastapi-samples\backend\.venv\Lib\site-packages\redis\asyncio\connection.py", line 322, in connect_check_health
    await self.on_connect_check_health(check_health=check_health)
  File "D:\Projects\fastapi-samples\backend\.venv\Lib\site-packages\redis\asyncio\connection.py", line 402, in on_connect_check_health
    auth_response = await self.read_response()
                    ^^^^^^^^^^^^^^^^^^^^^^^^^^
  File "D:\Projects\fastapi-samples\backend\.venv\Lib\site-packages\redis\asyncio\connection.py", line 591, in read_response
    response = await self._parser.read_response(
               ^^^^^^^^^^^^^^^^^^^^^^^^^^^^^^^^^
  File "D:\Projects\fastapi-samples\backend\.venv\Lib\site-packages\redis\_parsers\resp2.py", line 82, in read_response
    response = await self._read_response(disable_decoding=disable_decoding)
               ^^^^^^^^^^^^^^^^^^^^^^^^^^^^^^^^^^^^^^^^^^^^^^^^^^^^^^^^^^^^
  File "D:\Projects\fastapi-samples\backend\.venv\Lib\site-packages\redis\_parsers\resp2.py", line 102, in _read_response
    raise error
redis.exceptions.AuthenticationError: invalid username-password pair or user is disabled.

During handling of the above exception, another exception occurred:

Traceback (most recent call last):
  File "D:\Projects\fastapi-samples\backend\.venv\Lib\site-packages\starlette\routing.py", line 693, in lifespan
    async with self.lifespan_context(app) as maybe_state:
               ^^^^^^^^^^^^^^^^^^^^^^^^^^
  File "D:\Program Files\Python312\Lib\contextlib.py", line 210, in __aenter__
    return await anext(self.gen)
           ^^^^^^^^^^^^^^^^^^^^^
  File "D:\Projects\fastapi-samples\backend\.venv\Lib\site-packages\fastapi_pagination\api.py", line 347, in lifespan
    async with _original_lifespan_context(app) as maybe_state:
               ^^^^^^^^^^^^^^^^^^^^^^^^^^^^^^^
  File "D:\Program Files\Python312\Lib\contextlib.py", line 210, in __aenter__
    return await anext(self.gen)
           ^^^^^^^^^^^^^^^^^^^^^
  File "D:\Projects\fastapi-samples\backend\.venv\Lib\site-packages\fastapi\routing.py", line 133, in merged_lifespan
    async with original_context(app) as maybe_original_state:
               ^^^^^^^^^^^^^^^^^^^^^
  File "D:\Program Files\Python312\Lib\contextlib.py", line 210, in __aenter__
    return await anext(self.gen)
           ^^^^^^^^^^^^^^^^^^^^^
  File "D:\Projects\fastapi-samples\backend\core\register.py", line 37, in register_init
    await redis_client.open()
  File "D:\Projects\fastapi-samples\backend\database\redis.py", line 37, in open
    sys.exit()
SystemExit

2025-09-28 13:39:47.586 | ERROR    | - | Application startup failed. Exiting.
2025-09-28 13:39:58.062 | ERROR    | - | ❌ 数据库 redis 连接认证失败
2025-09-28 13:39:58.065 | ERROR    | - | Traceback (most recent call last):
  File "D:\Projects\fastapi-samples\backend\database\redis.py", line 31, in open
    await self.ping()
  File "D:\Projects\fastapi-samples\backend\.venv\Lib\site-packages\redis\asyncio\client.py", line 672, in execute_command
    conn = self.connection or await pool.get_connection()
                              ^^^^^^^^^^^^^^^^^^^^^^^^^^^
  File "D:\Projects\fastapi-samples\backend\.venv\Lib\site-packages\redis\asyncio\connection.py", line 1149, in get_connection
    await self.ensure_connection(connection)
  File "D:\Projects\fastapi-samples\backend\.venv\Lib\site-packages\redis\asyncio\connection.py", line 1182, in ensure_connection
    await connection.connect()
  File "D:\Projects\fastapi-samples\backend\.venv\Lib\site-packages\redis\asyncio\connection.py", line 296, in connect
    await self.connect_check_health(check_health=True)
  File "D:\Projects\fastapi-samples\backend\.venv\Lib\site-packages\redis\asyncio\connection.py", line 322, in connect_check_health
    await self.on_connect_check_health(check_health=check_health)
  File "D:\Projects\fastapi-samples\backend\.venv\Lib\site-packages\redis\asyncio\connection.py", line 402, in on_connect_check_health
    auth_response = await self.read_response()
                    ^^^^^^^^^^^^^^^^^^^^^^^^^^
  File "D:\Projects\fastapi-samples\backend\.venv\Lib\site-packages\redis\asyncio\connection.py", line 591, in read_response
    response = await self._parser.read_response(
               ^^^^^^^^^^^^^^^^^^^^^^^^^^^^^^^^^
  File "D:\Projects\fastapi-samples\backend\.venv\Lib\site-packages\redis\_parsers\resp2.py", line 82, in read_response
    response = await self._read_response(disable_decoding=disable_decoding)
               ^^^^^^^^^^^^^^^^^^^^^^^^^^^^^^^^^^^^^^^^^^^^^^^^^^^^^^^^^^^^
  File "D:\Projects\fastapi-samples\backend\.venv\Lib\site-packages\redis\_parsers\resp2.py", line 102, in _read_response
    raise error
redis.exceptions.AuthenticationError: invalid username-password pair or user is disabled.

During handling of the above exception, another exception occurred:

Traceback (most recent call last):
  File "D:\Projects\fastapi-samples\backend\.venv\Lib\site-packages\starlette\routing.py", line 693, in lifespan
    async with self.lifespan_context(app) as maybe_state:
               ^^^^^^^^^^^^^^^^^^^^^^^^^^
  File "D:\Program Files\Python312\Lib\contextlib.py", line 210, in __aenter__
    return await anext(self.gen)
           ^^^^^^^^^^^^^^^^^^^^^
  File "D:\Projects\fastapi-samples\backend\.venv\Lib\site-packages\fastapi_pagination\api.py", line 347, in lifespan
    async with _original_lifespan_context(app) as maybe_state:
               ^^^^^^^^^^^^^^^^^^^^^^^^^^^^^^^
  File "D:\Program Files\Python312\Lib\contextlib.py", line 210, in __aenter__
    return await anext(self.gen)
           ^^^^^^^^^^^^^^^^^^^^^
  File "D:\Projects\fastapi-samples\backend\.venv\Lib\site-packages\fastapi\routing.py", line 133, in merged_lifespan
    async with original_context(app) as maybe_original_state:
               ^^^^^^^^^^^^^^^^^^^^^
  File "D:\Program Files\Python312\Lib\contextlib.py", line 210, in __aenter__
    return await anext(self.gen)
           ^^^^^^^^^^^^^^^^^^^^^
  File "D:\Projects\fastapi-samples\backend\core\register.py", line 37, in register_init
    await redis_client.open()
  File "D:\Projects\fastapi-samples\backend\database\redis.py", line 37, in open
    sys.exit()
SystemExit

2025-09-28 13:39:58.068 | ERROR    | - | Application startup failed. Exiting.
2025-09-28 13:39:59.572 | ERROR    | - | ❌ 数据库 redis 连接认证失败
2025-09-28 13:39:59.577 | ERROR    | - | Traceback (most recent call last):
  File "D:\Projects\fastapi-samples\backend\database\redis.py", line 31, in open
    await self.ping()
  File "D:\Projects\fastapi-samples\backend\.venv\Lib\site-packages\redis\asyncio\client.py", line 672, in execute_command
    conn = self.connection or await pool.get_connection()
                              ^^^^^^^^^^^^^^^^^^^^^^^^^^^
  File "D:\Projects\fastapi-samples\backend\.venv\Lib\site-packages\redis\asyncio\connection.py", line 1149, in get_connection
    await self.ensure_connection(connection)
  File "D:\Projects\fastapi-samples\backend\.venv\Lib\site-packages\redis\asyncio\connection.py", line 1182, in ensure_connection
    await connection.connect()
  File "D:\Projects\fastapi-samples\backend\.venv\Lib\site-packages\redis\asyncio\connection.py", line 296, in connect
    await self.connect_check_health(check_health=True)
  File "D:\Projects\fastapi-samples\backend\.venv\Lib\site-packages\redis\asyncio\connection.py", line 322, in connect_check_health
    await self.on_connect_check_health(check_health=check_health)
  File "D:\Projects\fastapi-samples\backend\.venv\Lib\site-packages\redis\asyncio\connection.py", line 402, in on_connect_check_health
    auth_response = await self.read_response()
                    ^^^^^^^^^^^^^^^^^^^^^^^^^^
  File "D:\Projects\fastapi-samples\backend\.venv\Lib\site-packages\redis\asyncio\connection.py", line 591, in read_response
    response = await self._parser.read_response(
               ^^^^^^^^^^^^^^^^^^^^^^^^^^^^^^^^^
  File "D:\Projects\fastapi-samples\backend\.venv\Lib\site-packages\redis\_parsers\resp2.py", line 82, in read_response
    response = await self._read_response(disable_decoding=disable_decoding)
               ^^^^^^^^^^^^^^^^^^^^^^^^^^^^^^^^^^^^^^^^^^^^^^^^^^^^^^^^^^^^
  File "D:\Projects\fastapi-samples\backend\.venv\Lib\site-packages\redis\_parsers\resp2.py", line 102, in _read_response
    raise error
redis.exceptions.AuthenticationError: invalid username-password pair or user is disabled.

During handling of the above exception, another exception occurred:

Traceback (most recent call last):
  File "D:\Projects\fastapi-samples\backend\.venv\Lib\site-packages\starlette\routing.py", line 693, in lifespan
    async with self.lifespan_context(app) as maybe_state:
               ^^^^^^^^^^^^^^^^^^^^^^^^^^
  File "D:\Program Files\Python312\Lib\contextlib.py", line 210, in __aenter__
    return await anext(self.gen)
           ^^^^^^^^^^^^^^^^^^^^^
  File "D:\Projects\fastapi-samples\backend\.venv\Lib\site-packages\fastapi_pagination\api.py", line 347, in lifespan
    async with _original_lifespan_context(app) as maybe_state:
               ^^^^^^^^^^^^^^^^^^^^^^^^^^^^^^^
  File "D:\Program Files\Python312\Lib\contextlib.py", line 210, in __aenter__
    return await anext(self.gen)
           ^^^^^^^^^^^^^^^^^^^^^
  File "D:\Projects\fastapi-samples\backend\.venv\Lib\site-packages\fastapi\routing.py", line 133, in merged_lifespan
    async with original_context(app) as maybe_original_state:
               ^^^^^^^^^^^^^^^^^^^^^
  File "D:\Program Files\Python312\Lib\contextlib.py", line 210, in __aenter__
    return await anext(self.gen)
           ^^^^^^^^^^^^^^^^^^^^^
  File "D:\Projects\fastapi-samples\backend\core\register.py", line 37, in register_init
    await redis_client.open()
  File "D:\Projects\fastapi-samples\backend\database\redis.py", line 37, in open
    sys.exit()
SystemExit

2025-09-28 13:39:59.579 | ERROR    | - | Application startup failed. Exiting.
2025-09-28 13:40:01.106 | ERROR    | - | ❌ 数据库 redis 连接认证失败
2025-09-28 13:40:01.110 | ERROR    | - | Traceback (most recent call last):
  File "D:\Projects\fastapi-samples\backend\database\redis.py", line 31, in open
    await self.ping()
  File "D:\Projects\fastapi-samples\backend\.venv\Lib\site-packages\redis\asyncio\client.py", line 672, in execute_command
    conn = self.connection or await pool.get_connection()
                              ^^^^^^^^^^^^^^^^^^^^^^^^^^^
  File "D:\Projects\fastapi-samples\backend\.venv\Lib\site-packages\redis\asyncio\connection.py", line 1149, in get_connection
    await self.ensure_connection(connection)
  File "D:\Projects\fastapi-samples\backend\.venv\Lib\site-packages\redis\asyncio\connection.py", line 1182, in ensure_connection
    await connection.connect()
  File "D:\Projects\fastapi-samples\backend\.venv\Lib\site-packages\redis\asyncio\connection.py", line 296, in connect
    await self.connect_check_health(check_health=True)
  File "D:\Projects\fastapi-samples\backend\.venv\Lib\site-packages\redis\asyncio\connection.py", line 322, in connect_check_health
    await self.on_connect_check_health(check_health=check_health)
  File "D:\Projects\fastapi-samples\backend\.venv\Lib\site-packages\redis\asyncio\connection.py", line 402, in on_connect_check_health
    auth_response = await self.read_response()
                    ^^^^^^^^^^^^^^^^^^^^^^^^^^
  File "D:\Projects\fastapi-samples\backend\.venv\Lib\site-packages\redis\asyncio\connection.py", line 591, in read_response
    response = await self._parser.read_response(
               ^^^^^^^^^^^^^^^^^^^^^^^^^^^^^^^^^
  File "D:\Projects\fastapi-samples\backend\.venv\Lib\site-packages\redis\_parsers\resp2.py", line 82, in read_response
    response = await self._read_response(disable_decoding=disable_decoding)
               ^^^^^^^^^^^^^^^^^^^^^^^^^^^^^^^^^^^^^^^^^^^^^^^^^^^^^^^^^^^^
  File "D:\Projects\fastapi-samples\backend\.venv\Lib\site-packages\redis\_parsers\resp2.py", line 102, in _read_response
    raise error
redis.exceptions.AuthenticationError: invalid username-password pair or user is disabled.

During handling of the above exception, another exception occurred:

Traceback (most recent call last):
  File "D:\Projects\fastapi-samples\backend\.venv\Lib\site-packages\starlette\routing.py", line 693, in lifespan
    async with self.lifespan_context(app) as maybe_state:
               ^^^^^^^^^^^^^^^^^^^^^^^^^^
  File "D:\Program Files\Python312\Lib\contextlib.py", line 210, in __aenter__
    return await anext(self.gen)
           ^^^^^^^^^^^^^^^^^^^^^
  File "D:\Projects\fastapi-samples\backend\.venv\Lib\site-packages\fastapi_pagination\api.py", line 347, in lifespan
    async with _original_lifespan_context(app) as maybe_state:
               ^^^^^^^^^^^^^^^^^^^^^^^^^^^^^^^
  File "D:\Program Files\Python312\Lib\contextlib.py", line 210, in __aenter__
    return await anext(self.gen)
           ^^^^^^^^^^^^^^^^^^^^^
  File "D:\Projects\fastapi-samples\backend\.venv\Lib\site-packages\fastapi\routing.py", line 133, in merged_lifespan
    async with original_context(app) as maybe_original_state:
               ^^^^^^^^^^^^^^^^^^^^^
  File "D:\Program Files\Python312\Lib\contextlib.py", line 210, in __aenter__
    return await anext(self.gen)
           ^^^^^^^^^^^^^^^^^^^^^
  File "D:\Projects\fastapi-samples\backend\core\register.py", line 37, in register_init
    await redis_client.open()
  File "D:\Projects\fastapi-samples\backend\database\redis.py", line 37, in open
    sys.exit()
SystemExit

2025-09-28 13:40:01.112 | ERROR    | - | Application startup failed. Exiting.
2025-09-28 13:41:11.338 | ERROR    | - | ❌ 数据库 redis 连接认证失败
2025-09-28 13:41:11.342 | ERROR    | - | Traceback (most recent call last):
  File "D:\Projects\fastapi-samples\backend\database\redis.py", line 31, in open
    await self.ping()
  File "D:\Projects\fastapi-samples\backend\.venv\Lib\site-packages\redis\asyncio\client.py", line 672, in execute_command
    conn = self.connection or await pool.get_connection()
                              ^^^^^^^^^^^^^^^^^^^^^^^^^^^
  File "D:\Projects\fastapi-samples\backend\.venv\Lib\site-packages\redis\asyncio\connection.py", line 1149, in get_connection
    await self.ensure_connection(connection)
  File "D:\Projects\fastapi-samples\backend\.venv\Lib\site-packages\redis\asyncio\connection.py", line 1182, in ensure_connection
    await connection.connect()
  File "D:\Projects\fastapi-samples\backend\.venv\Lib\site-packages\redis\asyncio\connection.py", line 296, in connect
    await self.connect_check_health(check_health=True)
  File "D:\Projects\fastapi-samples\backend\.venv\Lib\site-packages\redis\asyncio\connection.py", line 322, in connect_check_health
    await self.on_connect_check_health(check_health=check_health)
  File "D:\Projects\fastapi-samples\backend\.venv\Lib\site-packages\redis\asyncio\connection.py", line 402, in on_connect_check_health
    auth_response = await self.read_response()
                    ^^^^^^^^^^^^^^^^^^^^^^^^^^
  File "D:\Projects\fastapi-samples\backend\.venv\Lib\site-packages\redis\asyncio\connection.py", line 591, in read_response
    response = await self._parser.read_response(
               ^^^^^^^^^^^^^^^^^^^^^^^^^^^^^^^^^
  File "D:\Projects\fastapi-samples\backend\.venv\Lib\site-packages\redis\_parsers\resp2.py", line 82, in read_response
    response = await self._read_response(disable_decoding=disable_decoding)
               ^^^^^^^^^^^^^^^^^^^^^^^^^^^^^^^^^^^^^^^^^^^^^^^^^^^^^^^^^^^^
  File "D:\Projects\fastapi-samples\backend\.venv\Lib\site-packages\redis\_parsers\resp2.py", line 102, in _read_response
    raise error
redis.exceptions.AuthenticationError: invalid username-password pair or user is disabled.

During handling of the above exception, another exception occurred:

Traceback (most recent call last):
  File "D:\Projects\fastapi-samples\backend\.venv\Lib\site-packages\starlette\routing.py", line 693, in lifespan
    async with self.lifespan_context(app) as maybe_state:
               ^^^^^^^^^^^^^^^^^^^^^^^^^^
  File "D:\Program Files\Python312\Lib\contextlib.py", line 210, in __aenter__
    return await anext(self.gen)
           ^^^^^^^^^^^^^^^^^^^^^
  File "D:\Projects\fastapi-samples\backend\.venv\Lib\site-packages\fastapi_pagination\api.py", line 347, in lifespan
    async with _original_lifespan_context(app) as maybe_state:
               ^^^^^^^^^^^^^^^^^^^^^^^^^^^^^^^
  File "D:\Program Files\Python312\Lib\contextlib.py", line 210, in __aenter__
    return await anext(self.gen)
           ^^^^^^^^^^^^^^^^^^^^^
  File "D:\Projects\fastapi-samples\backend\.venv\Lib\site-packages\fastapi\routing.py", line 133, in merged_lifespan
    async with original_context(app) as maybe_original_state:
               ^^^^^^^^^^^^^^^^^^^^^
  File "D:\Program Files\Python312\Lib\contextlib.py", line 210, in __aenter__
    return await anext(self.gen)
           ^^^^^^^^^^^^^^^^^^^^^
  File "D:\Projects\fastapi-samples\backend\core\register.py", line 37, in register_init
    await redis_client.open()
  File "D:\Projects\fastapi-samples\backend\database\redis.py", line 37, in open
    sys.exit()
SystemExit

2025-09-28 13:41:11.344 | ERROR    | - | Application startup failed. Exiting.
2025-09-28 13:48:39.690 | ERROR    | - | ❌ 数据库 redis 连接认证失败
2025-09-28 13:48:39.694 | ERROR    | - | Traceback (most recent call last):
  File "D:\Projects\fastapi-samples\backend\database\redis.py", line 31, in open
    await self.ping()
  File "D:\Projects\fastapi-samples\backend\.venv\Lib\site-packages\redis\asyncio\client.py", line 672, in execute_command
    conn = self.connection or await pool.get_connection()
                              ^^^^^^^^^^^^^^^^^^^^^^^^^^^
  File "D:\Projects\fastapi-samples\backend\.venv\Lib\site-packages\redis\asyncio\connection.py", line 1149, in get_connection
    await self.ensure_connection(connection)
  File "D:\Projects\fastapi-samples\backend\.venv\Lib\site-packages\redis\asyncio\connection.py", line 1182, in ensure_connection
    await connection.connect()
  File "D:\Projects\fastapi-samples\backend\.venv\Lib\site-packages\redis\asyncio\connection.py", line 296, in connect
    await self.connect_check_health(check_health=True)
  File "D:\Projects\fastapi-samples\backend\.venv\Lib\site-packages\redis\asyncio\connection.py", line 322, in connect_check_health
    await self.on_connect_check_health(check_health=check_health)
  File "D:\Projects\fastapi-samples\backend\.venv\Lib\site-packages\redis\asyncio\connection.py", line 402, in on_connect_check_health
    auth_response = await self.read_response()
                    ^^^^^^^^^^^^^^^^^^^^^^^^^^
  File "D:\Projects\fastapi-samples\backend\.venv\Lib\site-packages\redis\asyncio\connection.py", line 591, in read_response
    response = await self._parser.read_response(
               ^^^^^^^^^^^^^^^^^^^^^^^^^^^^^^^^^
  File "D:\Projects\fastapi-samples\backend\.venv\Lib\site-packages\redis\_parsers\resp2.py", line 82, in read_response
    response = await self._read_response(disable_decoding=disable_decoding)
               ^^^^^^^^^^^^^^^^^^^^^^^^^^^^^^^^^^^^^^^^^^^^^^^^^^^^^^^^^^^^
  File "D:\Projects\fastapi-samples\backend\.venv\Lib\site-packages\redis\_parsers\resp2.py", line 102, in _read_response
    raise error
redis.exceptions.AuthenticationError: invalid username-password pair or user is disabled.

During handling of the above exception, another exception occurred:

Traceback (most recent call last):
  File "D:\Projects\fastapi-samples\backend\.venv\Lib\site-packages\starlette\routing.py", line 693, in lifespan
    async with self.lifespan_context(app) as maybe_state:
               ^^^^^^^^^^^^^^^^^^^^^^^^^^
  File "D:\Program Files\Python312\Lib\contextlib.py", line 210, in __aenter__
    return await anext(self.gen)
           ^^^^^^^^^^^^^^^^^^^^^
  File "D:\Projects\fastapi-samples\backend\.venv\Lib\site-packages\fastapi_pagination\api.py", line 347, in lifespan
    async with _original_lifespan_context(app) as maybe_state:
               ^^^^^^^^^^^^^^^^^^^^^^^^^^^^^^^
  File "D:\Program Files\Python312\Lib\contextlib.py", line 210, in __aenter__
    return await anext(self.gen)
           ^^^^^^^^^^^^^^^^^^^^^
  File "D:\Projects\fastapi-samples\backend\.venv\Lib\site-packages\fastapi\routing.py", line 133, in merged_lifespan
    async with original_context(app) as maybe_original_state:
               ^^^^^^^^^^^^^^^^^^^^^
  File "D:\Program Files\Python312\Lib\contextlib.py", line 210, in __aenter__
    return await anext(self.gen)
           ^^^^^^^^^^^^^^^^^^^^^
  File "D:\Projects\fastapi-samples\backend\core\register.py", line 37, in register_init
    await redis_client.open()
  File "D:\Projects\fastapi-samples\backend\database\redis.py", line 37, in open
    sys.exit()
SystemExit

2025-09-28 13:48:39.696 | ERROR    | - | Application startup failed. Exiting.
2025-09-28 13:48:39.707 | ERROR    | - | ❌ 数据库 redis 连接认证失败
2025-09-28 13:48:39.711 | ERROR    | - | Traceback (most recent call last):
  File "D:\Projects\fastapi-samples\backend\database\redis.py", line 31, in open
    await self.ping()
  File "D:\Projects\fastapi-samples\backend\.venv\Lib\site-packages\redis\asyncio\client.py", line 672, in execute_command
    conn = self.connection or await pool.get_connection()
                              ^^^^^^^^^^^^^^^^^^^^^^^^^^^
  File "D:\Projects\fastapi-samples\backend\.venv\Lib\site-packages\redis\asyncio\connection.py", line 1149, in get_connection
    await self.ensure_connection(connection)
  File "D:\Projects\fastapi-samples\backend\.venv\Lib\site-packages\redis\asyncio\connection.py", line 1182, in ensure_connection
    await connection.connect()
  File "D:\Projects\fastapi-samples\backend\.venv\Lib\site-packages\redis\asyncio\connection.py", line 296, in connect
    await self.connect_check_health(check_health=True)
  File "D:\Projects\fastapi-samples\backend\.venv\Lib\site-packages\redis\asyncio\connection.py", line 322, in connect_check_health
    await self.on_connect_check_health(check_health=check_health)
  File "D:\Projects\fastapi-samples\backend\.venv\Lib\site-packages\redis\asyncio\connection.py", line 402, in on_connect_check_health
    auth_response = await self.read_response()
                    ^^^^^^^^^^^^^^^^^^^^^^^^^^
  File "D:\Projects\fastapi-samples\backend\.venv\Lib\site-packages\redis\asyncio\connection.py", line 591, in read_response
    response = await self._parser.read_response(
               ^^^^^^^^^^^^^^^^^^^^^^^^^^^^^^^^^
  File "D:\Projects\fastapi-samples\backend\.venv\Lib\site-packages\redis\_parsers\resp2.py", line 82, in read_response
    response = await self._read_response(disable_decoding=disable_decoding)
               ^^^^^^^^^^^^^^^^^^^^^^^^^^^^^^^^^^^^^^^^^^^^^^^^^^^^^^^^^^^^
  File "D:\Projects\fastapi-samples\backend\.venv\Lib\site-packages\redis\_parsers\resp2.py", line 102, in _read_response
    raise error
redis.exceptions.AuthenticationError: invalid username-password pair or user is disabled.

During handling of the above exception, another exception occurred:

Traceback (most recent call last):
  File "D:\Projects\fastapi-samples\backend\.venv\Lib\site-packages\starlette\routing.py", line 693, in lifespan
    async with self.lifespan_context(app) as maybe_state:
               ^^^^^^^^^^^^^^^^^^^^^^^^^^
  File "D:\Program Files\Python312\Lib\contextlib.py", line 210, in __aenter__
    return await anext(self.gen)
           ^^^^^^^^^^^^^^^^^^^^^
  File "D:\Projects\fastapi-samples\backend\.venv\Lib\site-packages\fastapi_pagination\api.py", line 347, in lifespan
    async with _original_lifespan_context(app) as maybe_state:
               ^^^^^^^^^^^^^^^^^^^^^^^^^^^^^^^
  File "D:\Program Files\Python312\Lib\contextlib.py", line 210, in __aenter__
    return await anext(self.gen)
           ^^^^^^^^^^^^^^^^^^^^^
  File "D:\Projects\fastapi-samples\backend\.venv\Lib\site-packages\fastapi\routing.py", line 133, in merged_lifespan
    async with original_context(app) as maybe_original_state:
               ^^^^^^^^^^^^^^^^^^^^^
  File "D:\Program Files\Python312\Lib\contextlib.py", line 210, in __aenter__
    return await anext(self.gen)
           ^^^^^^^^^^^^^^^^^^^^^
  File "D:\Projects\fastapi-samples\backend\core\register.py", line 37, in register_init
    await redis_client.open()
  File "D:\Projects\fastapi-samples\backend\database\redis.py", line 37, in open
    sys.exit()
SystemExit

2025-09-28 13:48:39.712 | ERROR    | - | Application startup failed. Exiting.
2025-09-28 13:48:57.839 | ERROR    | - | ❌ 数据库 redis 连接认证失败
2025-09-28 13:48:57.842 | ERROR    | - | Traceback (most recent call last):
  File "D:\Projects\fastapi-samples\backend\database\redis.py", line 31, in open
    await self.ping()
  File "D:\Projects\fastapi-samples\backend\.venv\Lib\site-packages\redis\asyncio\client.py", line 672, in execute_command
    conn = self.connection or await pool.get_connection()
                              ^^^^^^^^^^^^^^^^^^^^^^^^^^^
  File "D:\Projects\fastapi-samples\backend\.venv\Lib\site-packages\redis\asyncio\connection.py", line 1149, in get_connection
    await self.ensure_connection(connection)
  File "D:\Projects\fastapi-samples\backend\.venv\Lib\site-packages\redis\asyncio\connection.py", line 1182, in ensure_connection
    await connection.connect()
  File "D:\Projects\fastapi-samples\backend\.venv\Lib\site-packages\redis\asyncio\connection.py", line 296, in connect
    await self.connect_check_health(check_health=True)
  File "D:\Projects\fastapi-samples\backend\.venv\Lib\site-packages\redis\asyncio\connection.py", line 322, in connect_check_health
    await self.on_connect_check_health(check_health=check_health)
  File "D:\Projects\fastapi-samples\backend\.venv\Lib\site-packages\redis\asyncio\connection.py", line 402, in on_connect_check_health
    auth_response = await self.read_response()
                    ^^^^^^^^^^^^^^^^^^^^^^^^^^
  File "D:\Projects\fastapi-samples\backend\.venv\Lib\site-packages\redis\asyncio\connection.py", line 591, in read_response
    response = await self._parser.read_response(
               ^^^^^^^^^^^^^^^^^^^^^^^^^^^^^^^^^
  File "D:\Projects\fastapi-samples\backend\.venv\Lib\site-packages\redis\_parsers\resp2.py", line 82, in read_response
    response = await self._read_response(disable_decoding=disable_decoding)
               ^^^^^^^^^^^^^^^^^^^^^^^^^^^^^^^^^^^^^^^^^^^^^^^^^^^^^^^^^^^^
  File "D:\Projects\fastapi-samples\backend\.venv\Lib\site-packages\redis\_parsers\resp2.py", line 102, in _read_response
    raise error
redis.exceptions.AuthenticationError: invalid username-password pair or user is disabled.

During handling of the above exception, another exception occurred:

Traceback (most recent call last):
  File "D:\Projects\fastapi-samples\backend\.venv\Lib\site-packages\starlette\routing.py", line 693, in lifespan
    async with self.lifespan_context(app) as maybe_state:
               ^^^^^^^^^^^^^^^^^^^^^^^^^^
  File "D:\Program Files\Python312\Lib\contextlib.py", line 210, in __aenter__
    return await anext(self.gen)
           ^^^^^^^^^^^^^^^^^^^^^
  File "D:\Projects\fastapi-samples\backend\.venv\Lib\site-packages\fastapi_pagination\api.py", line 347, in lifespan
    async with _original_lifespan_context(app) as maybe_state:
               ^^^^^^^^^^^^^^^^^^^^^^^^^^^^^^^
  File "D:\Program Files\Python312\Lib\contextlib.py", line 210, in __aenter__
    return await anext(self.gen)
           ^^^^^^^^^^^^^^^^^^^^^
  File "D:\Projects\fastapi-samples\backend\.venv\Lib\site-packages\fastapi\routing.py", line 133, in merged_lifespan
    async with original_context(app) as maybe_original_state:
               ^^^^^^^^^^^^^^^^^^^^^
  File "D:\Program Files\Python312\Lib\contextlib.py", line 210, in __aenter__
    return await anext(self.gen)
           ^^^^^^^^^^^^^^^^^^^^^
  File "D:\Projects\fastapi-samples\backend\core\register.py", line 37, in register_init
    await redis_client.open()
  File "D:\Projects\fastapi-samples\backend\database\redis.py", line 37, in open
    sys.exit()
SystemExit

2025-09-28 13:48:57.843 | ERROR    | - | Application startup failed. Exiting.
