2025-09-28 16:06:55.461 | ERROR    | 498de82c98314ad0af57a29c3833091e | Exception in ASGI application

2025-09-28 16:06:55.617 | ERROR    | 0e1583fb479143dfbaeefae30c624e32 | Exception in ASGI application

2025-09-28 16:07:46.251 | ERROR    | 32d46e791c964183b2ecac650a4e5d6c | Exception in ASGI application

2025-09-28 16:07:46.293 | ERROR    | e8d6d5fc4a5b4b50a9d890d5312a9341 | Exception in ASGI application

2025-09-28 16:08:47.948 | ERROR    | b22ae2c633104a4cab6175faced36eca | Exception in ASGI application

2025-09-28 16:08:47.974 | ERROR    | d82c0e9d8acc4dd39a04b41eb6918491 | Exception in ASGI application

2025-09-28 16:37:02.628 | ERROR    | f9631bf23c4540f6baafeae6b7f42feb | Exception in ASGI application

2025-09-28 16:37:52.029 | ERROR    | 60eec9f0293c4f2498be666f9ab2a5bf | Exception in ASGI application

2025-09-28 16:37:52.367 | ERROR    | 94896059bf284a98be89f002fdb33866 | Exception in ASGI application

2025-09-28 16:39:02.296 | ERROR    | 661e16452a07404c8b79cf20d149727a | Exception in ASGI application

2025-09-28 16:51:44.965 | ERROR    | 56d8b91247c2446bba89419c1fb466c3 | Exception in ASGI application

2025-09-28 16:52:20.097 | ERROR    | 99c172ea17f243ad9a394ba2148ca6d3 | Exception in ASGI application

2025-09-28 17:00:38.724 | ERROR    | - | Traceback (most recent call last):
  File "D:\Program Files\Python312\Lib\asyncio\runners.py", line 118, in run
    return self._loop.run_until_complete(task)
           ^^^^^^^^^^^^^^^^^^^^^^^^^^^^^^^^^^^
  File "D:\Program Files\Python312\Lib\asyncio\base_events.py", line 691, in run_until_complete
    return future.result()
           ^^^^^^^^^^^^^^^
asyncio.exceptions.CancelledError

During handling of the above exception, another exception occurred:

Traceback (most recent call last):
  File "D:\Program Files\Python312\Lib\asyncio\runners.py", line 195, in run
    return runner.run(main)
           ^^^^^^^^^^^^^^^^
  File "D:\Program Files\Python312\Lib\asyncio\runners.py", line 123, in run
    raise KeyboardInterrupt()
KeyboardInterrupt

During handling of the above exception, another exception occurred:

Traceback (most recent call last):
  File "D:\Program Files\Python312\Lib\site-packages\starlette\routing.py", line 701, in lifespan
    await receive()
  File "D:\Program Files\Python312\Lib\site-packages\uvicorn\lifespan\on.py", line 137, in receive
    return await self.receive_queue.get()
           ^^^^^^^^^^^^^^^^^^^^^^^^^^^^^^
  File "D:\Program Files\Python312\Lib\asyncio\queues.py", line 158, in get
    await getter
asyncio.exceptions.CancelledError

2025-09-28 17:00:38.729 | ERROR    | - | Traceback (most recent call last):
  File "D:\Program Files\Python312\Lib\asyncio\runners.py", line 118, in run
    return self._loop.run_until_complete(task)
           ^^^^^^^^^^^^^^^^^^^^^^^^^^^^^^^^^^^
  File "D:\Program Files\Python312\Lib\asyncio\base_events.py", line 691, in run_until_complete
    return future.result()
           ^^^^^^^^^^^^^^^
asyncio.exceptions.CancelledError

During handling of the above exception, another exception occurred:

Traceback (most recent call last):
  File "D:\Program Files\Python312\Lib\asyncio\runners.py", line 195, in run
    return runner.run(main)
           ^^^^^^^^^^^^^^^^
  File "D:\Program Files\Python312\Lib\asyncio\runners.py", line 123, in run
    raise KeyboardInterrupt()
KeyboardInterrupt

During handling of the above exception, another exception occurred:

Traceback (most recent call last):
  File "D:\Program Files\Python312\Lib\site-packages\starlette\routing.py", line 701, in lifespan
    await receive()
  File "D:\Program Files\Python312\Lib\site-packages\uvicorn\lifespan\on.py", line 137, in receive
    return await self.receive_queue.get()
           ^^^^^^^^^^^^^^^^^^^^^^^^^^^^^^
  File "D:\Program Files\Python312\Lib\asyncio\queues.py", line 158, in get
    await getter
asyncio.exceptions.CancelledError

2025-09-28 17:02:46.540 | ERROR    | 045cfdde05e943b0a651826dd6536483 | Exception in ASGI application

2025-09-28 17:03:48.179 | ERROR    | 7b5135bd2e2f4fa6bc98e2dae2adf714 | Exception in ASGI application

2025-09-28 17:04:19.814 | ERROR    | 0ea12966ad004a9ea108eff7f7f57bff | Exception in ASGI application

2025-09-28 17:09:04.031 | ERROR    | 4bc5ee0bfac441a7a1c5a653b066b368 | Exception in ASGI application

2025-09-28 17:13:09.779 | ERROR    | 1443efa1d0244e5da13e309738b497fc | Exception in ASGI application

2025-09-28 17:14:55.941 | ERROR    | 339b9937b65e4cd3a8d6645f9f162ecb | Exception in ASGI application

2025-09-28 17:14:56.196 | ERROR    | 54f06ed4eb7546b8ae58711287c2b654 | Exception in ASGI application

2025-09-28 17:21:56.811 | ERROR    | 86485e662e1140c09cf6d502c8652df1 | Exception in ASGI application

2025-09-28 17:23:15.055 | ERROR    | 7a3adde9e7d242e2ac582a9c7ff8cd5f | Exception in ASGI application

2025-09-28 17:33:24.093 | ERROR    | 468fa04de9aa42109229234a86130233 | Exception in ASGI application

2025-09-28 17:33:24.475 | ERROR    | 546be1aa04ea44ae9bac7f8f6c3ad632 | Exception in ASGI application

2025-09-28 17:33:24.603 | ERROR    | b5af7ac084844b05931cb78ffa611730 | Exception in ASGI application

2025-09-28 17:33:25.054 | ERROR    | 7a2754d6d24f405285716aad35e852b4 | Exception in ASGI application

2025-09-28 17:34:14.923 | ERROR    | - | Traceback (most recent call last):
  File "D:\Program Files\Python312\Lib\asyncio\runners.py", line 195, in run
    return runner.run(main)
           ^^^^^^^^^^^^^^^^
  File "D:\Program Files\Python312\Lib\asyncio\runners.py", line 118, in run
    return self._loop.run_until_complete(task)
           ^^^^^^^^^^^^^^^^^^^^^^^^^^^^^^^^^^^
  File "D:\Program Files\Python312\Lib\asyncio\base_events.py", line 678, in run_until_complete
    self.run_forever()
  File "D:\Program Files\Python312\Lib\asyncio\base_events.py", line 645, in run_forever
    self._run_once()
  File "D:\Program Files\Python312\Lib\asyncio\base_events.py", line 1999, in _run_once
    handle._run()
  File "D:\Program Files\Python312\Lib\asyncio\events.py", line 88, in _run
    self._context.run(self._callback, *self._args)
  File "D:\Program Files\Python312\Lib\site-packages\uvicorn\server.py", line 70, in serve
    with self.capture_signals():
         ^^^^^^^^^^^^^^^^^^^^^^
  File "D:\Program Files\Python312\Lib\contextlib.py", line 144, in __exit__
    next(self.gen)
  File "D:\Program Files\Python312\Lib\site-packages\uvicorn\server.py", line 331, in capture_signals
    signal.raise_signal(captured_signal)
  File "D:\Program Files\Python312\Lib\asyncio\runners.py", line 157, in _on_sigint
    raise KeyboardInterrupt()
KeyboardInterrupt

During handling of the above exception, another exception occurred:

Traceback (most recent call last):
  File "D:\Program Files\Python312\Lib\site-packages\starlette\routing.py", line 701, in lifespan
    await receive()
  File "D:\Program Files\Python312\Lib\site-packages\uvicorn\lifespan\on.py", line 137, in receive
    return await self.receive_queue.get()
           ^^^^^^^^^^^^^^^^^^^^^^^^^^^^^^
  File "D:\Program Files\Python312\Lib\asyncio\queues.py", line 158, in get
    await getter
asyncio.exceptions.CancelledError

2025-09-28 17:38:59.254 | ERROR    | - | Traceback (most recent call last):
  File "D:\Program Files\Python312\Lib\asyncio\runners.py", line 195, in run
    return runner.run(main)
           ^^^^^^^^^^^^^^^^
  File "D:\Program Files\Python312\Lib\asyncio\runners.py", line 118, in run
    return self._loop.run_until_complete(task)
           ^^^^^^^^^^^^^^^^^^^^^^^^^^^^^^^^^^^
  File "D:\Program Files\Python312\Lib\asyncio\base_events.py", line 678, in run_until_complete
    self.run_forever()
  File "D:\Program Files\Python312\Lib\asyncio\base_events.py", line 645, in run_forever
    self._run_once()
  File "D:\Program Files\Python312\Lib\asyncio\base_events.py", line 1999, in _run_once
    handle._run()
  File "D:\Program Files\Python312\Lib\asyncio\events.py", line 88, in _run
    self._context.run(self._callback, *self._args)
  File "D:\Projects\fastapi-samples\backend\.venv\Lib\site-packages\uvicorn\server.py", line 68, in serve
    with self.capture_signals():
         ^^^^^^^^^^^^^^^^^^^^^^
  File "D:\Program Files\Python312\Lib\contextlib.py", line 144, in __exit__
    next(self.gen)
  File "D:\Projects\fastapi-samples\backend\.venv\Lib\site-packages\uvicorn\server.py", line 328, in capture_signals
    signal.raise_signal(captured_signal)
  File "D:\Program Files\Python312\Lib\asyncio\runners.py", line 157, in _on_sigint
    raise KeyboardInterrupt()
KeyboardInterrupt

During handling of the above exception, another exception occurred:

Traceback (most recent call last):
  File "D:\Projects\fastapi-samples\backend\.venv\Lib\site-packages\starlette\routing.py", line 700, in lifespan
    await receive()
  File "D:\Projects\fastapi-samples\backend\.venv\Lib\site-packages\uvicorn\lifespan\on.py", line 137, in receive
    return await self.receive_queue.get()
           ^^^^^^^^^^^^^^^^^^^^^^^^^^^^^^
  File "D:\Program Files\Python312\Lib\asyncio\queues.py", line 158, in get
    await getter
asyncio.exceptions.CancelledError

2025-09-28 17:45:18.120 | ERROR    | 2a4fac02f38e45c5b6637cd6f6b7ad9f | Exception in ASGI application

2025-09-28 18:02:02.209 | ERROR    | - | Traceback (most recent call last):
  File "D:\Program Files\Python312\Lib\asyncio\runners.py", line 118, in run
    return self._loop.run_until_complete(task)
           ^^^^^^^^^^^^^^^^^^^^^^^^^^^^^^^^^^^
  File "D:\Program Files\Python312\Lib\asyncio\base_events.py", line 691, in run_until_complete
    return future.result()
           ^^^^^^^^^^^^^^^
asyncio.exceptions.CancelledError

During handling of the above exception, another exception occurred:

Traceback (most recent call last):
  File "D:\Program Files\Python312\Lib\asyncio\runners.py", line 195, in run
    return runner.run(main)
           ^^^^^^^^^^^^^^^^
  File "D:\Program Files\Python312\Lib\asyncio\runners.py", line 123, in run
    raise KeyboardInterrupt()
KeyboardInterrupt

During handling of the above exception, another exception occurred:

Traceback (most recent call last):
  File "D:\Projects\fastapi-samples\backend\.venv\Lib\site-packages\starlette\routing.py", line 700, in lifespan
    await receive()
  File "D:\Projects\fastapi-samples\backend\.venv\Lib\site-packages\uvicorn\lifespan\on.py", line 137, in receive
    return await self.receive_queue.get()
           ^^^^^^^^^^^^^^^^^^^^^^^^^^^^^^
  File "D:\Program Files\Python312\Lib\asyncio\queues.py", line 158, in get
    await getter
asyncio.exceptions.CancelledError

2025-09-28 18:03:29.218 | ERROR    | - | Traceback (most recent call last):
  File "D:\Program Files\Python312\Lib\asyncio\runners.py", line 118, in run
    return self._loop.run_until_complete(task)
           ^^^^^^^^^^^^^^^^^^^^^^^^^^^^^^^^^^^
  File "D:\Program Files\Python312\Lib\asyncio\base_events.py", line 691, in run_until_complete
    return future.result()
           ^^^^^^^^^^^^^^^
asyncio.exceptions.CancelledError

During handling of the above exception, another exception occurred:

Traceback (most recent call last):
  File "D:\Program Files\Python312\Lib\asyncio\runners.py", line 195, in run
    return runner.run(main)
           ^^^^^^^^^^^^^^^^
  File "D:\Program Files\Python312\Lib\asyncio\runners.py", line 123, in run
    raise KeyboardInterrupt()
KeyboardInterrupt

During handling of the above exception, another exception occurred:

Traceback (most recent call last):
  File "D:\Projects\fastapi-samples\backend\.venv\Lib\site-packages\starlette\routing.py", line 700, in lifespan
    await receive()
  File "D:\Projects\fastapi-samples\backend\.venv\Lib\site-packages\uvicorn\lifespan\on.py", line 137, in receive
    return await self.receive_queue.get()
           ^^^^^^^^^^^^^^^^^^^^^^^^^^^^^^
  File "D:\Program Files\Python312\Lib\asyncio\queues.py", line 158, in get
    await getter
asyncio.exceptions.CancelledError

2025-09-28 18:03:31.223 | ERROR    | - | Traceback (most recent call last):
  File "D:\Program Files\Python312\Lib\asyncio\runners.py", line 118, in run
    return self._loop.run_until_complete(task)
           ^^^^^^^^^^^^^^^^^^^^^^^^^^^^^^^^^^^
  File "D:\Program Files\Python312\Lib\asyncio\base_events.py", line 691, in run_until_complete
    return future.result()
           ^^^^^^^^^^^^^^^
asyncio.exceptions.CancelledError

During handling of the above exception, another exception occurred:

Traceback (most recent call last):
  File "D:\Program Files\Python312\Lib\asyncio\runners.py", line 195, in run
    return runner.run(main)
           ^^^^^^^^^^^^^^^^
  File "D:\Program Files\Python312\Lib\asyncio\runners.py", line 123, in run
    raise KeyboardInterrupt()
KeyboardInterrupt

During handling of the above exception, another exception occurred:

Traceback (most recent call last):
  File "D:\Projects\fastapi-samples\backend\.venv\Lib\site-packages\starlette\routing.py", line 700, in lifespan
    await receive()
  File "D:\Projects\fastapi-samples\backend\.venv\Lib\site-packages\uvicorn\lifespan\on.py", line 137, in receive
    return await self.receive_queue.get()
           ^^^^^^^^^^^^^^^^^^^^^^^^^^^^^^
  File "D:\Program Files\Python312\Lib\asyncio\queues.py", line 158, in get
    await getter
asyncio.exceptions.CancelledError

2025-09-28 18:03:33.429 | ERROR    | - | Traceback (most recent call last):
  File "D:\Program Files\Python312\Lib\asyncio\runners.py", line 118, in run
    return self._loop.run_until_complete(task)
           ^^^^^^^^^^^^^^^^^^^^^^^^^^^^^^^^^^^
  File "D:\Program Files\Python312\Lib\asyncio\base_events.py", line 691, in run_until_complete
    return future.result()
           ^^^^^^^^^^^^^^^
asyncio.exceptions.CancelledError

During handling of the above exception, another exception occurred:

Traceback (most recent call last):
  File "D:\Program Files\Python312\Lib\asyncio\runners.py", line 195, in run
    return runner.run(main)
           ^^^^^^^^^^^^^^^^
  File "D:\Program Files\Python312\Lib\asyncio\runners.py", line 123, in run
    raise KeyboardInterrupt()
KeyboardInterrupt

During handling of the above exception, another exception occurred:

Traceback (most recent call last):
  File "D:\Projects\fastapi-samples\backend\.venv\Lib\site-packages\starlette\routing.py", line 700, in lifespan
    await receive()
  File "D:\Projects\fastapi-samples\backend\.venv\Lib\site-packages\uvicorn\lifespan\on.py", line 137, in receive
    return await self.receive_queue.get()
           ^^^^^^^^^^^^^^^^^^^^^^^^^^^^^^
  File "D:\Program Files\Python312\Lib\asyncio\queues.py", line 158, in get
    await getter
asyncio.exceptions.CancelledError

2025-09-28 18:05:34.644 | ERROR    | - | Traceback (most recent call last):
  File "D:\Program Files\Python312\Lib\asyncio\runners.py", line 118, in run
    return self._loop.run_until_complete(task)
           ^^^^^^^^^^^^^^^^^^^^^^^^^^^^^^^^^^^
  File "D:\Program Files\Python312\Lib\asyncio\base_events.py", line 691, in run_until_complete
    return future.result()
           ^^^^^^^^^^^^^^^
asyncio.exceptions.CancelledError

During handling of the above exception, another exception occurred:

Traceback (most recent call last):
  File "D:\Program Files\Python312\Lib\asyncio\runners.py", line 195, in run
    return runner.run(main)
           ^^^^^^^^^^^^^^^^
  File "D:\Program Files\Python312\Lib\asyncio\runners.py", line 123, in run
    raise KeyboardInterrupt()
KeyboardInterrupt

During handling of the above exception, another exception occurred:

Traceback (most recent call last):
  File "D:\Projects\fastapi-samples\backend\.venv\Lib\site-packages\starlette\routing.py", line 700, in lifespan
    await receive()
  File "D:\Projects\fastapi-samples\backend\.venv\Lib\site-packages\uvicorn\lifespan\on.py", line 137, in receive
    return await self.receive_queue.get()
           ^^^^^^^^^^^^^^^^^^^^^^^^^^^^^^
  File "D:\Program Files\Python312\Lib\asyncio\queues.py", line 158, in get
    await getter
asyncio.exceptions.CancelledError

2025-09-28 18:05:36.658 | ERROR    | - | Traceback (most recent call last):
  File "D:\Program Files\Python312\Lib\asyncio\runners.py", line 118, in run
    return self._loop.run_until_complete(task)
           ^^^^^^^^^^^^^^^^^^^^^^^^^^^^^^^^^^^
  File "D:\Program Files\Python312\Lib\asyncio\base_events.py", line 691, in run_until_complete
    return future.result()
           ^^^^^^^^^^^^^^^
asyncio.exceptions.CancelledError

During handling of the above exception, another exception occurred:

Traceback (most recent call last):
  File "D:\Program Files\Python312\Lib\asyncio\runners.py", line 195, in run
    return runner.run(main)
           ^^^^^^^^^^^^^^^^
  File "D:\Program Files\Python312\Lib\asyncio\runners.py", line 123, in run
    raise KeyboardInterrupt()
KeyboardInterrupt

During handling of the above exception, another exception occurred:

Traceback (most recent call last):
  File "D:\Projects\fastapi-samples\backend\.venv\Lib\site-packages\starlette\routing.py", line 700, in lifespan
    await receive()
  File "D:\Projects\fastapi-samples\backend\.venv\Lib\site-packages\uvicorn\lifespan\on.py", line 137, in receive
    return await self.receive_queue.get()
           ^^^^^^^^^^^^^^^^^^^^^^^^^^^^^^
  File "D:\Program Files\Python312\Lib\asyncio\queues.py", line 158, in get
    await getter
asyncio.exceptions.CancelledError

2025-09-28 18:05:38.689 | ERROR    | - | Traceback (most recent call last):
  File "D:\Program Files\Python312\Lib\asyncio\runners.py", line 118, in run
    return self._loop.run_until_complete(task)
           ^^^^^^^^^^^^^^^^^^^^^^^^^^^^^^^^^^^
  File "D:\Program Files\Python312\Lib\asyncio\base_events.py", line 691, in run_until_complete
    return future.result()
           ^^^^^^^^^^^^^^^
asyncio.exceptions.CancelledError

During handling of the above exception, another exception occurred:

Traceback (most recent call last):
  File "D:\Program Files\Python312\Lib\asyncio\runners.py", line 195, in run
    return runner.run(main)
           ^^^^^^^^^^^^^^^^
  File "D:\Program Files\Python312\Lib\asyncio\runners.py", line 123, in run
    raise KeyboardInterrupt()
KeyboardInterrupt

During handling of the above exception, another exception occurred:

Traceback (most recent call last):
  File "D:\Projects\fastapi-samples\backend\.venv\Lib\site-packages\starlette\routing.py", line 700, in lifespan
    await receive()
  File "D:\Projects\fastapi-samples\backend\.venv\Lib\site-packages\uvicorn\lifespan\on.py", line 137, in receive
    return await self.receive_queue.get()
           ^^^^^^^^^^^^^^^^^^^^^^^^^^^^^^
  File "D:\Program Files\Python312\Lib\asyncio\queues.py", line 158, in get
    await getter
asyncio.exceptions.CancelledError

2025-09-28 18:06:20.979 | ERROR    | - | Traceback (most recent call last):
  File "D:\Program Files\Python312\Lib\asyncio\runners.py", line 118, in run
    return self._loop.run_until_complete(task)
           ^^^^^^^^^^^^^^^^^^^^^^^^^^^^^^^^^^^
  File "D:\Program Files\Python312\Lib\asyncio\base_events.py", line 691, in run_until_complete
    return future.result()
           ^^^^^^^^^^^^^^^
asyncio.exceptions.CancelledError

During handling of the above exception, another exception occurred:

Traceback (most recent call last):
  File "D:\Program Files\Python312\Lib\asyncio\runners.py", line 195, in run
    return runner.run(main)
           ^^^^^^^^^^^^^^^^
  File "D:\Program Files\Python312\Lib\asyncio\runners.py", line 123, in run
    raise KeyboardInterrupt()
KeyboardInterrupt

During handling of the above exception, another exception occurred:

Traceback (most recent call last):
  File "D:\Projects\fastapi-samples\backend\.venv\Lib\site-packages\starlette\routing.py", line 700, in lifespan
    await receive()
  File "D:\Projects\fastapi-samples\backend\.venv\Lib\site-packages\uvicorn\lifespan\on.py", line 137, in receive
    return await self.receive_queue.get()
           ^^^^^^^^^^^^^^^^^^^^^^^^^^^^^^
  File "D:\Program Files\Python312\Lib\asyncio\queues.py", line 158, in get
    await getter
asyncio.exceptions.CancelledError

2025-09-28 18:06:22.981 | ERROR    | - | Traceback (most recent call last):
  File "D:\Program Files\Python312\Lib\asyncio\runners.py", line 118, in run
    return self._loop.run_until_complete(task)
           ^^^^^^^^^^^^^^^^^^^^^^^^^^^^^^^^^^^
  File "D:\Program Files\Python312\Lib\asyncio\base_events.py", line 691, in run_until_complete
    return future.result()
           ^^^^^^^^^^^^^^^
asyncio.exceptions.CancelledError

During handling of the above exception, another exception occurred:

Traceback (most recent call last):
  File "D:\Program Files\Python312\Lib\asyncio\runners.py", line 195, in run
    return runner.run(main)
           ^^^^^^^^^^^^^^^^
  File "D:\Program Files\Python312\Lib\asyncio\runners.py", line 123, in run
    raise KeyboardInterrupt()
KeyboardInterrupt

During handling of the above exception, another exception occurred:

Traceback (most recent call last):
  File "D:\Projects\fastapi-samples\backend\.venv\Lib\site-packages\starlette\routing.py", line 700, in lifespan
    await receive()
  File "D:\Projects\fastapi-samples\backend\.venv\Lib\site-packages\uvicorn\lifespan\on.py", line 137, in receive
    return await self.receive_queue.get()
           ^^^^^^^^^^^^^^^^^^^^^^^^^^^^^^
  File "D:\Program Files\Python312\Lib\asyncio\queues.py", line 158, in get
    await getter
asyncio.exceptions.CancelledError

2025-09-28 18:06:25.026 | ERROR    | - | Traceback (most recent call last):
  File "D:\Program Files\Python312\Lib\asyncio\runners.py", line 118, in run
    return self._loop.run_until_complete(task)
           ^^^^^^^^^^^^^^^^^^^^^^^^^^^^^^^^^^^
  File "D:\Program Files\Python312\Lib\asyncio\base_events.py", line 691, in run_until_complete
    return future.result()
           ^^^^^^^^^^^^^^^
asyncio.exceptions.CancelledError

During handling of the above exception, another exception occurred:

Traceback (most recent call last):
  File "D:\Program Files\Python312\Lib\asyncio\runners.py", line 195, in run
    return runner.run(main)
           ^^^^^^^^^^^^^^^^
  File "D:\Program Files\Python312\Lib\asyncio\runners.py", line 123, in run
    raise KeyboardInterrupt()
KeyboardInterrupt

During handling of the above exception, another exception occurred:

Traceback (most recent call last):
  File "D:\Projects\fastapi-samples\backend\.venv\Lib\site-packages\starlette\routing.py", line 700, in lifespan
    await receive()
  File "D:\Projects\fastapi-samples\backend\.venv\Lib\site-packages\uvicorn\lifespan\on.py", line 137, in receive
    return await self.receive_queue.get()
           ^^^^^^^^^^^^^^^^^^^^^^^^^^^^^^
  File "D:\Program Files\Python312\Lib\asyncio\queues.py", line 158, in get
    await getter
asyncio.exceptions.CancelledError

2025-09-28 18:06:27.017 | ERROR    | - | Traceback (most recent call last):
  File "D:\Program Files\Python312\Lib\asyncio\runners.py", line 118, in run
    return self._loop.run_until_complete(task)
           ^^^^^^^^^^^^^^^^^^^^^^^^^^^^^^^^^^^
  File "D:\Program Files\Python312\Lib\asyncio\base_events.py", line 691, in run_until_complete
    return future.result()
           ^^^^^^^^^^^^^^^
asyncio.exceptions.CancelledError

During handling of the above exception, another exception occurred:

Traceback (most recent call last):
  File "D:\Program Files\Python312\Lib\asyncio\runners.py", line 195, in run
    return runner.run(main)
           ^^^^^^^^^^^^^^^^
  File "D:\Program Files\Python312\Lib\asyncio\runners.py", line 123, in run
    raise KeyboardInterrupt()
KeyboardInterrupt

During handling of the above exception, another exception occurred:

Traceback (most recent call last):
  File "D:\Projects\fastapi-samples\backend\.venv\Lib\site-packages\starlette\routing.py", line 700, in lifespan
    await receive()
  File "D:\Projects\fastapi-samples\backend\.venv\Lib\site-packages\uvicorn\lifespan\on.py", line 137, in receive
    return await self.receive_queue.get()
           ^^^^^^^^^^^^^^^^^^^^^^^^^^^^^^
  File "D:\Program Files\Python312\Lib\asyncio\queues.py", line 158, in get
    await getter
asyncio.exceptions.CancelledError

2025-09-28 18:07:20.080 | ERROR    | - | Traceback (most recent call last):
  File "D:\Program Files\Python312\Lib\asyncio\runners.py", line 118, in run
    return self._loop.run_until_complete(task)
           ^^^^^^^^^^^^^^^^^^^^^^^^^^^^^^^^^^^
  File "D:\Program Files\Python312\Lib\asyncio\base_events.py", line 691, in run_until_complete
    return future.result()
           ^^^^^^^^^^^^^^^
asyncio.exceptions.CancelledError

During handling of the above exception, another exception occurred:

Traceback (most recent call last):
  File "D:\Program Files\Python312\Lib\asyncio\runners.py", line 195, in run
    return runner.run(main)
           ^^^^^^^^^^^^^^^^
  File "D:\Program Files\Python312\Lib\asyncio\runners.py", line 123, in run
    raise KeyboardInterrupt()
KeyboardInterrupt

During handling of the above exception, another exception occurred:

Traceback (most recent call last):
  File "D:\Projects\fastapi-samples\backend\.venv\Lib\site-packages\starlette\routing.py", line 700, in lifespan
    await receive()
  File "D:\Projects\fastapi-samples\backend\.venv\Lib\site-packages\uvicorn\lifespan\on.py", line 137, in receive
    return await self.receive_queue.get()
           ^^^^^^^^^^^^^^^^^^^^^^^^^^^^^^
  File "D:\Program Files\Python312\Lib\asyncio\queues.py", line 158, in get
    await getter
asyncio.exceptions.CancelledError

